Workbook

Sheet TABELA GERAL
A1: COLAR | B1: CHEFE | C1: ETERNID | D1: MARTE | E1: FINALID | F1: ORIGEM | G1: PILAR | H1: TROVÃO | I1: HO-OH | K1: CAMISA | L1: CHEFE | M1: ETERNID | N1: MARTE | O1: FINALID | P1: ORIGEM | Q1: PILAR | R1: TROVÃO | S1: HO-OH | U1: BOTA | V1: CHEFE | W1: ETERNID | X1: MARTE | Y1: FINALID | Z1: ORIGEM | AA1: PILAR | AB1: TROVÃO | AC1: HO-OH
A2: Titânio I | B2: =COUNTIFS(COLAR!$B:$B,'TABELA GERAL'!B1) -> 0 | C2: =COUNTIFS(COLAR!$B:$B,'TABELA GERAL'!C1) -> 0 | D2: =COUNTIFS(COLAR!$B:$B,'TABELA GERAL'!D1) -> 0 | E2: =COUNTIFS(COLAR!$B:$B,'TABELA GERAL'!E1) -> 0 | F2: =COUNTIFS(COLAR!$B:$B,'TABELA GERAL'!F1) -> 1 | G2: =COUNTIFS(COLAR!$B:$B,'TABELA GERAL'!G1) -> 0 | H2: =COUNTIFS(COLAR!$B:$B,'TABELA GERAL'!H1) -> 0 | I2: =COUNTIFS(COLAR!$B:$B,'TABELA GERAL'!I1) -> 0 | K2: Titânio I | L2: =COUNTIFS(CAMISA!$B:$B,'TABELA GERAL'!L1) -> 0 | M2: =COUNTIFS(CAMISA!$B:$B,'TABELA GERAL'!M1) -> 0 | N2: =COUNTIFS(CAMISA!$B:$B,'TABELA GERAL'!N1) -> 1 | O2: =COUNTIFS(CAMISA!$B:$B,'TABELA GERAL'!O1) -> 0 | P2: =COUNTIFS(CAMISA!$B:$B,'TABELA GERAL'!P1) -> 0 | Q2: =COUNTIFS(CAMISA!$B:$B,'TABELA GERAL'!Q1) -> 0 | R2: =COUNTIFS(CAMISA!$B:$B,'TABELA GERAL'!R1) -> 0 | S2: =COUNTIFS(CAMISA!$B:$B,'TABELA GERAL'!S1) -> 0 | U2: Titânio I | V2: =COUNTIFS(BOTA!$B:$B,'TABELA GERAL'!V1) -> 1 | W2: =COUNTIFS(BOTA!$B:$B,'TABELA GERAL'!W1) -> 0 | X2: =COUNTIFS(BOTA!$B:$B,'TABELA GERAL'!X1) -> 0 | Y2: =COUNTIFS(BOTA!$B:$B,'TABELA GERAL'!Y1) -> 0 | Z2: =COUNTIFS(BOTA!$B:$B,'TABELA GERAL'!Z1) -> 2 | AA2: =COUNTIFS(BOTA!$B:$B,'TABELA GERAL'!AA1) -> 0 | AB2: =COUNTIFS(BOTA!$B:$B,'TABELA GERAL'!AB1) -> 0 | AC2: =COUNTIFS(BOTA!$B:$B,'TABELA GERAL'!AC1) -> 0
A3: Titânio II | B3: =COUNTIFS(COLAR!$D:$D,'TABELA GERAL'!B1) -> 0 | C3: =COUNTIFS(COLAR!$D:$D,'TABELA GERAL'!C1) -> 0 | D3: =COUNTIFS(COLAR!$D:$D,'TABELA GERAL'!D1) -> 1 | E3: =COUNTIFS(COLAR!$D:$D,'TABELA GERAL'!E1) -> 0 | F3: =COUNTIFS(COLAR!$D:$D,'TABELA GERAL'!F1) -> 2 | G3: =COUNTIFS(COLAR!$D:$D,'TABELA GERAL'!G1) -> 0 | H3: =COUNTIFS(COLAR!$D:$D,'TABELA GERAL'!H1) -> 0 | I3: =COUNTIFS(COLAR!$D:$D,'TABELA GERAL'!I1) -> 0 | K3: Titânio II | L3: =COUNTIFS(CAMISA!$D:$D,'TABELA GERAL'!L1) -> 0 | M3: =COUNTIFS(CAMISA!$D:$D,'TABELA GERAL'!M1) -> 1 | N3: =COUNTIFS(CAMISA!$D:$D,'TABELA GERAL'!N1) -> 0 | O3: =COUNTIFS(CAMISA!$D:$D,'TABELA GERAL'!O1) -> 1 | P3: =COUNTIFS(CAMISA!$D:$D,'TABELA GERAL'!P1) -> 1 | Q3: =COUNTIFS(CAMISA!$D:$D,'TABELA GERAL'!Q1) -> 3 | R3: =COUNTIFS(CAMISA!$D:$D,'TABELA GERAL'!R1) -> 0 | S3: =COUNTIFS(CAMISA!$D:$D,'TABELA GERAL'!S1) -> 1 | U3: Titânio II | V3: =COUNTIFS(BOTA!$D:$D,'TABELA GERAL'!V1) -> 0 | W3: =COUNTIFS(BOTA!$D:$D,'TABELA GERAL'!W1) -> 0 | X3: =COUNTIFS(BOTA!$D:$D,'TABELA GERAL'!X1) -> 1 | Y3: =COUNTIFS(BOTA!$D:$D,'TABELA GERAL'!Y1) -> 0 | Z3: =COUNTIFS(BOTA!$D:$D,'TABELA GERAL'!Z1) -> 1 | AA3: =COUNTIFS(BOTA!$D:$D,'TABELA GERAL'!AA1) -> 0 | AB3: =COUNTIFS(BOTA!$D:$D,'TABELA GERAL'!AB1) -> 0 | AC3: =COUNTIFS(BOTA!$D:$D,'TABELA GERAL'!AC1) -> 0
A4: Titânio III | B4: =COUNTIFS(COLAR!$F:$F,'TABELA GERAL'!B1) -> 0 | C4: =COUNTIFS(COLAR!$F:$F,'TABELA GERAL'!C1) -> 0 | D4: =COUNTIFS(COLAR!$F:$F,'TABELA GERAL'!D1) -> 1 | E4: =COUNTIFS(COLAR!$F:$F,'TABELA GERAL'!E1) -> 1 | F4: =COUNTIFS(COLAR!$F:$F,'TABELA GERAL'!F1) -> 1 | G4: =COUNTIFS(COLAR!$F:$F,'TABELA GERAL'!G1) -> 0 | H4: =COUNTIFS(COLAR!$F:$F,'TABELA GERAL'!H1) -> 0 | I4: =COUNTIFS(COLAR!$F:$F,'TABELA GERAL'!I1) -> 0 | K4: Titânio III | L4: =COUNTIFS(CAMISA!$F:$F,'TABELA GERAL'!L1) -> 0 | M4: =COUNTIFS(CAMISA!$F:$F,'TABELA GERAL'!M1) -> 0 | N4: =COUNTIFS(CAMISA!$F:$F,'TABELA GERAL'!N1) -> 0 | O4: =COUNTIFS(CAMISA!$F:$F,'TABELA GERAL'!O1) -> 0 | P4: =COUNTIFS(CAMISA!$F:$F,'TABELA GERAL'!P1) -> 1 | Q4: =COUNTIFS(CAMISA!$F:$F,'TABELA GERAL'!Q1) -> 0 | R4: =COUNTIFS(CAMISA!$F:$F,'TABELA GERAL'!R1) -> 0 | S4: =COUNTIFS(CAMISA!$F:$F,'TABELA GERAL'!S1) -> 0 | U4: Titânio III | V4: =COUNTIFS(BOTA!$F:$F,'TABELA GERAL'!V1) -> 0 | W4: =COUNTIFS(BOTA!$F:$F,'TABELA GERAL'!W1) -> 0 | X4: =COUNTIFS(BOTA!$F:$F,'TABELA GERAL'!X1) -> 1 | Y4: =COUNTIFS(BOTA!$F:$F,'TABELA GERAL'!Y1) -> 0 | Z4: =COUNTIFS(BOTA!$F:$F,'TABELA GERAL'!Z1) -> 0 | AA4: =COUNTIFS(BOTA!$F:$F,'TABELA GERAL'!AA1) -> 0 | AB4: =COUNTIFS(BOTA!$F:$F,'TABELA GERAL'!AB1) -> 0 | AC4: =COUNTIFS(BOTA!$F:$F,'TABELA GERAL'!AC1) -> 0
A5: Titânio IV | B5: =COUNTIFS(COLAR!$H:$H,'TABELA GERAL'!B1) -> 1 | C5: =COUNTIFS(COLAR!$H:$H,'TABELA GERAL'!C1) -> 3 | D5: =COUNTIFS(COLAR!$H:$H,'TABELA GERAL'!D1) -> 0 | E5: =COUNTIFS(COLAR!$H:$H,'TABELA GERAL'!E1) -> 0 | F5: =COUNTIFS(COLAR!$H:$H,'TABELA GERAL'!F1) -> 0 | G5: =COUNTIFS(COLAR!$H:$H,'TABELA GERAL'!G1) -> 0 | H5: =COUNTIFS(COLAR!$H:$H,'TABELA GERAL'!H1) -> 1 | I5: =COUNTIFS(COLAR!$H:$H,'TABELA GERAL'!I1) -> 0 | K5: Titânio IV | L5: =COUNTIFS(CAMISA!$H:$H,'TABELA GERAL'!L1) -> 0 | M5: =COUNTIFS(CAMISA!$H:$H,'TABELA GERAL'!M1) -> 0 | N5: =COUNTIFS(CAMISA!$H:$H,'TABELA GERAL'!N1) -> 0 | O5: =COUNTIFS(CAMISA!$H:$H,'TABELA GERAL'!O1) -> 2 | P5: =COUNTIFS(CAMISA!$H:$H,'TABELA GERAL'!P1) -> 2 | Q5: =COUNTIFS(CAMISA!$H:$H,'TABELA GERAL'!Q1) -> 0 | R5: =COUNTIFS(CAMISA!$H:$H,'TABELA GERAL'!R1) -> 0 | S5: =COUNTIFS(CAMISA!$H:$H,'TABELA GERAL'!S1) -> 1 | U5: Titânio IV | V5: =COUNTIFS(BOTA!$H:$H,'TABELA GERAL'!V1) -> 0 | W5: =COUNTIFS(BOTA!$H:$H,'TABELA GERAL'!W1) -> 1 | X5: =COUNTIFS(BOTA!$H:$H,'TABELA GERAL'!X1) -> 0 | Y5: =COUNTIFS(BOTA!$H:$H,'TABELA GERAL'!Y1) -> 0 | Z5: =COUNTIFS(BOTA!$H:$H,'TABELA GERAL'!Z1) -> 1 | AA5: =COUNTIFS(BOTA!$H:$H,'TABELA GERAL'!AA1) -> 1 | AB5: =COUNTIFS(BOTA!$H:$H,'TABELA GERAL'!AB1) -> 1 | AC5: =COUNTIFS(BOTA!$H:$H,'TABELA GERAL'!AC1) -> 0
A6: Titânio V | B6: =COUNTIFS(COLAR!$J:$J,'TABELA GERAL'!B1) -> 0 | C6: =COUNTIFS(COLAR!$J:$J,'TABELA GERAL'!C1) -> 0 | D6: =COUNTIFS(COLAR!$J:$J,'TABELA GERAL'!D1) -> 0 | E6: =COUNTIFS(COLAR!$J:$J,'TABELA GERAL'!E1) -> 2 | F6: =COUNTIFS(COLAR!$J:$J,'TABELA GERAL'!F1) -> 1 | G6: =COUNTIFS(COLAR!$J:$J,'TABELA GERAL'!G1) -> 0 | H6: =COUNTIFS(COLAR!$J:$J,'TABELA GERAL'!H1) -> 0 | I6: =COUNTIFS(COLAR!$J:$J,'TABELA GERAL'!I1) -> 0 | K6: Titânio V | L6: =COUNTIFS(CAMISA!$J:$J,'TABELA GERAL'!L1) -> 0 | M6: =COUNTIFS(CAMISA!$J:$J,'TABELA GERAL'!M1) -> 0 | N6: =COUNTIFS(CAMISA!$J:$J,'TABELA GERAL'!N1) -> 1 | O6: =COUNTIFS(CAMISA!$J:$J,'TABELA GERAL'!O1) -> 2 | P6: =COUNTIFS(CAMISA!$J:$J,'TABELA GERAL'!P1) -> 0 | Q6: =COUNTIFS(CAMISA!$J:$J,'TABELA GERAL'!Q1) -> 4 | R6: =COUNTIFS(CAMISA!$J:$J,'TABELA GERAL'!R1) -> 0 | S6: =COUNTIFS(CAMISA!$J:$J,'TABELA GERAL'!S1) -> 0 | U6: Titânio V | V6: =COUNTIFS(BOTA!$J:$J,'TABELA GERAL'!V1) -> 0 | W6: =COUNTIFS(BOTA!$J:$J,'TABELA GERAL'!W1) -> 0 | X6: =COUNTIFS(BOTA!$J:$J,'TABELA GERAL'!X1) -> 2 | Y6: =COUNTIFS(BOTA!$J:$J,'TABELA GERAL'!Y1) -> 0 | Z6: =COUNTIFS(BOTA!$J:$J,'TABELA GERAL'!Z1) -> 2 | AA6: =COUNTIFS(BOTA!$J:$J,'TABELA GERAL'!AA1) -> 0 | AB6: =COUNTIFS(BOTA!$J:$J,'TABELA GERAL'!AB1) -> 0 | AC6: =COUNTIFS(BOTA!$J:$J,'TABELA GERAL'!AC1) -> 1
A7: Estrelar I | B7: =COUNTIFS(COLAR!$L:$L,'TABELA GERAL'!B1) -> 1 | C7: =COUNTIFS(COLAR!$L:$L,'TABELA GERAL'!C1) -> 0 | D7: =COUNTIFS(COLAR!$L:$L,'TABELA GERAL'!D1) -> 0 | E7: =COUNTIFS(COLAR!$L:$L,'TABELA GERAL'!E1) -> 2 | F7: =COUNTIFS(COLAR!$L:$L,'TABELA GERAL'!F1) -> 0 | G7: =COUNTIFS(COLAR!$L:$L,'TABELA GERAL'!G1) -> 0 | H7: =COUNTIFS(COLAR!$L:$L,'TABELA GERAL'!H1) -> 0 | I7: =COUNTIFS(COLAR!$L:$L,'TABELA GERAL'!I1) -> 0 | K7: Estrelar I | L7: =COUNTIFS(CAMISA!$L:$L,'TABELA GERAL'!L1) -> 0 | M7: =COUNTIFS(CAMISA!$L:$L,'TABELA GERAL'!M1) -> 0 | N7: =COUNTIFS(CAMISA!$L:$L,'TABELA GERAL'!N1) -> 1 | O7: =COUNTIFS(CAMISA!$L:$L,'TABELA GERAL'!O1) -> 0 | P7: =COUNTIFS(CAMISA!$L:$L,'TABELA GERAL'!P1) -> 3 | Q7: =COUNTIFS(CAMISA!$L:$L,'TABELA GERAL'!Q1) -> 0 | R7: =COUNTIFS(CAMISA!$L:$L,'TABELA GERAL'!R1) -> 0 | S7: =COUNTIFS(CAMISA!$L:$L,'TABELA GERAL'!S1) -> 0 | U7: Estrelar I | V7: =COUNTIFS(BOTA!$L:$L,'TABELA GERAL'!V1) -> 0 | W7: =COUNTIFS(BOTA!$L:$L,'TABELA GERAL'!W1) -> 1 | X7: =COUNTIFS(BOTA!$L:$L,'TABELA GERAL'!X1) -> 0 | Y7: =COUNTIFS(BOTA!$L:$L,'TABELA GERAL'!Y1) -> 0 | Z7: =COUNTIFS(BOTA!$L:$L,'TABELA GERAL'!Z1) -> 0 | AA7: =COUNTIFS(BOTA!$L:$L,'TABELA GERAL'!AA1) -> 0 | AB7: =COUNTIFS(BOTA!$L:$L,'TABELA GERAL'!AB1) -> 0 | AC7: =COUNTIFS(BOTA!$L:$L,'TABELA GERAL'!AC1) -> 0
A8: Estrelar II | B8: =COUNTIFS(COLAR!$N:$N,'TABELA GERAL'!B1) -> 0 | C8: =COUNTIFS(COLAR!$N:$N,'TABELA GERAL'!C1) -> 0 | D8: =COUNTIFS(COLAR!$N:$N,'TABELA GERAL'!D1) -> 0 | E8: =COUNTIFS(COLAR!$N:$N,'TABELA GERAL'!E1) -> 1 | F8: =COUNTIFS(COLAR!$N:$N,'TABELA GERAL'!F1) -> 0 | G8: =COUNTIFS(COLAR!$N:$N,'TABELA GERAL'!G1) -> 1 | H8: =COUNTIFS(COLAR!$N:$N,'TABELA GERAL'!H1) -> 0 | I8: =COUNTIFS(COLAR!$N:$N,'TABELA GERAL'!I1) -> 0 | K8: Estrelar II | L8: =COUNTIFS(CAMISA!$N:$N,'TABELA GERAL'!L1) -> 0 | M8: =COUNTIFS(CAMISA!$N:$N,'TABELA GERAL'!M1) -> 0 | N8: =COUNTIFS(CAMISA!$N:$N,'TABELA GERAL'!N1) -> 0 | O8: =COUNTIFS(CAMISA!$N:$N,'TABELA GERAL'!O1) -> 0 | P8: =COUNTIFS(CAMISA!$N:$N,'TABELA GERAL'!P1) -> 1 | Q8: =COUNTIFS(CAMISA!$N:$N,'TABELA GERAL'!Q1) -> 0 | R8: =COUNTIFS(CAMISA!$N:$N,'TABELA GERAL'!R1) -> 0 | S8: =COUNTIFS(CAMISA!$N:$N,'TABELA GERAL'!S1) -> 0 | U8: Estrelar II | V8: =COUNTIFS(BOTA!$N:$N,'TABELA GERAL'!V1) -> 0 | W8: =COUNTIFS(BOTA!$N:$N,'TABELA GERAL'!W1) -> 0 | X8: =COUNTIFS(BOTA!$N:$N,'TABELA GERAL'!X1) -> 0 | Y8: =COUNTIFS(BOTA!$N:$N,'TABELA GERAL'!Y1) -> 0 | Z8: =COUNTIFS(BOTA!$N:$N,'TABELA GERAL'!Z1) -> 0 | AA8: =COUNTIFS(BOTA!$N:$N,'TABELA GERAL'!AA1) -> 1 | AB8: =COUNTIFS(BOTA!$N:$N,'TABELA GERAL'!AB1) -> 0 | AC8: =COUNTIFS(BOTA!$N:$N,'TABELA GERAL'!AC1) -> 0
A9: Estrelar III | B9: =COUNTIFS(COLAR!$P:$P,'TABELA GERAL'!B1) -> 0 | C9: =COUNTIFS(COLAR!$P:$P,'TABELA GERAL'!C1) -> 0 | D9: =COUNTIFS(COLAR!$P:$P,'TABELA GERAL'!D1) -> 1 | E9: =COUNTIFS(COLAR!$P:$P,'TABELA GERAL'!E1) -> 0 | F9: =COUNTIFS(COLAR!$P:$P,'TABELA GERAL'!F1) -> 0 | G9: =COUNTIFS(COLAR!$P:$P,'TABELA GERAL'!G1) -> 0 | H9: =COUNTIFS(COLAR!$P:$P,'TABELA GERAL'!H1) -> 0 | I9: =COUNTIFS(COLAR!$P:$P,'TABELA GERAL'!I1) -> 0 | K9: Estrelar III | L9: =COUNTIFS(CAMISA!$P:$P,'TABELA GERAL'!L1) -> 0 | M9: =COUNTIFS(CAMISA!$P:$P,'TABELA GERAL'!M1) -> 0 | N9: =COUNTIFS(CAMISA!$P:$P,'TABELA GERAL'!N1) -> 0 | O9: =COUNTIFS(CAMISA!$P:$P,'TABELA GERAL'!O1) -> 0 | P9: =COUNTIFS(CAMISA!$P:$P,'TABELA GERAL'!P1) -> 0 | Q9: =COUNTIFS(CAMISA!$P:$P,'TABELA GERAL'!Q1) -> 2 | R9: =COUNTIFS(CAMISA!$P:$P,'TABELA GERAL'!R1) -> 0 | S9: =COUNTIFS(CAMISA!$P:$P,'TABELA GERAL'!S1) -> 0 | U9: Estrelar III | V9: =COUNTIFS(BOTA!$P:$P,'TABELA GERAL'!V1) -> 0 | W9: =COUNTIFS(BOTA!$P:$P,'TABELA GERAL'!W1) -> 0 | X9: =COUNTIFS(BOTA!$P:$P,'TABELA GERAL'!X1) -> 0 | Y9: =COUNTIFS(BOTA!$P:$P,'TABELA GERAL'!Y1) -> 0 | Z9: =COUNTIFS(BOTA!$P:$P,'TABELA GERAL'!Z1) -> 0 | AA9: =COUNTIFS(BOTA!$P:$P,'TABELA GERAL'!AA1) -> 0 | AB9: =COUNTIFS(BOTA!$P:$P,'TABELA GERAL'!AB1) -> 0 | AC9: =COUNTIFS(BOTA!$P:$P,'TABELA GERAL'!AC1) -> 0
A10: Estrelar IV | B10: =COUNTIFS(COLAR!$R:$R,'TABELA GERAL'!B1) -> 1 | C10: =COUNTIFS(COLAR!$R:$R,'TABELA GERAL'!C1) -> 0 | D10: =COUNTIFS(COLAR!$R:$R,'TABELA GERAL'!D1) -> 1 | E10: =COUNTIFS(COLAR!$R:$R,'TABELA GERAL'!E1) -> 0 | F10: =COUNTIFS(COLAR!$R:$R,'TABELA GERAL'!F1) -> 0 | G10: =COUNTIFS(COLAR!$R:$R,'TABELA GERAL'!G1) -> 1 | H10: =COUNTIFS(COLAR!$R:$R,'TABELA GERAL'!H1) -> 0 | I10: =COUNTIFS(COLAR!$R:$R,'TABELA GERAL'!I1) -> 0 | K10: Estrelar IV | L10: =COUNTIFS(CAMISA!$R:$R,'TABELA GERAL'!L1) -> 1 | M10: =COUNTIFS(CAMISA!$R:$R,'TABELA GERAL'!M1) -> 1 | N10: =COUNTIFS(CAMISA!$R:$R,'TABELA GERAL'!N1) -> 0 | O10: =COUNTIFS(CAMISA!$R:$R,'TABELA GERAL'!O1) -> 0 | P10: =COUNTIFS(CAMISA!$R:$R,'TABELA GERAL'!P1) -> 0 | Q10: =COUNTIFS(CAMISA!$R:$R,'TABELA GERAL'!Q1) -> 1 | R10: =COUNTIFS(CAMISA!$R:$R,'TABELA GERAL'!R1) -> 0 | S10: =COUNTIFS(CAMISA!$R:$R,'TABELA GERAL'!S1) -> 1 | U10: Estrelar IV | V10: =COUNTIFS(BOTA!$R:$R,'TABELA GERAL'!V1) -> 0 | W10: =COUNTIFS(BOTA!$R:$R,'TABELA GERAL'!W1) -> 0 | X10: =COUNTIFS(BOTA!$R:$R,'TABELA GERAL'!X1) -> 0 | Y10: =COUNTIFS(BOTA!$R:$R,'TABELA GERAL'!Y1) -> 1 | Z10: =COUNTIFS(BOTA!$R:$R,'TABELA GERAL'!Z1) -> 1 | AA10: =COUNTIFS(BOTA!$R:$R,'TABELA GERAL'!AA1) -> 1 | AB10: =COUNTIFS(BOTA!$R:$R,'TABELA GERAL'!AB1) -> 0 | AC10: =COUNTIFS(BOTA!$R:$R,'TABELA GERAL'!AC1) -> 0
A11: Estrelar V | B11: =COUNTIFS(COLAR!$T:$T,'TABELA GERAL'!B1) -> 0 | C11: =COUNTIFS(COLAR!$T:$T,'TABELA GERAL'!C1) -> 1 | D11: =COUNTIFS(COLAR!$T:$T,'TABELA GERAL'!D1) -> 0 | E11: =COUNTIFS(COLAR!$T:$T,'TABELA GERAL'!E1) -> 1 | F11: =COUNTIFS(COLAR!$T:$T,'TABELA GERAL'!F1) -> 0 | G11: =COUNTIFS(COLAR!$T:$T,'TABELA GERAL'!G1) -> 0 | H11: =COUNTIFS(COLAR!$T:$T,'TABELA GERAL'!H1) -> 0 | I11: =COUNTIFS(COLAR!$T:$T,'TABELA GERAL'!I1) -> 0 | K11: Estrelar V | L11: =COUNTIFS(CAMISA!$T:$T,'TABELA GERAL'!L1) -> 0 | M11: =COUNTIFS(CAMISA!$T:$T,'TABELA GERAL'!M1) -> 1 | N11: =COUNTIFS(CAMISA!$T:$T,'TABELA GERAL'!N1) -> 0 | O11: =COUNTIFS(CAMISA!$T:$T,'TABELA GERAL'!O1) -> 0 | P11: =COUNTIFS(CAMISA!$T:$T,'TABELA GERAL'!P1) -> 0 | Q11: =COUNTIFS(CAMISA!$T:$T,'TABELA GERAL'!Q1) -> 1 | R11: =COUNTIFS(CAMISA!$T:$T,'TABELA GERAL'!R1) -> 0 | S11: =COUNTIFS(CAMISA!$T:$T,'TABELA GERAL'!S1) -> 0 | U11: Estrelar V | V11: =COUNTIFS(BOTA!$T:$T,'TABELA GERAL'!V1) -> 0 | W11: =COUNTIFS(BOTA!$T:$T,'TABELA GERAL'!W1) -> 0 | X11: =COUNTIFS(BOTA!$T:$T,'TABELA GERAL'!X1) -> 0 | Y11: =COUNTIFS(BOTA!$T:$T,'TABELA GERAL'!Y1) -> 1 | Z11: =COUNTIFS(BOTA!$T:$T,'TABELA GERAL'!Z1) -> 0 | AA11: =COUNTIFS(BOTA!$T:$T,'TABELA GERAL'!AA1) -> 0 | AB11: =COUNTIFS(BOTA!$T:$T,'TABELA GERAL'!AB1) -> 0 | AC11: =COUNTIFS(BOTA!$T:$T,'TABELA GERAL'!AC1) -> 0
A12: Sacrifício I | B12: =COUNTIFS(COLAR!$V:$V,'TABELA GERAL'!B1) -> 0 | C12: =COUNTIFS(COLAR!$V:$V,'TABELA GERAL'!C1) -> 1 | D12: =COUNTIFS(COLAR!$V:$V,'TABELA GERAL'!D1) -> 1 | E12: =COUNTIFS(COLAR!$V:$V,'TABELA GERAL'!E1) -> 0 | F12: =COUNTIFS(COLAR!$V:$V,'TABELA GERAL'!F1) -> 1 | G12: =COUNTIFS(COLAR!$V:$V,'TABELA GERAL'!G1) -> 0 | H12: =COUNTIFS(COLAR!$V:$V,'TABELA GERAL'!H1) -> 0 | I12: =COUNTIFS(COLAR!$V:$V,'TABELA GERAL'!I1) -> 0 | K12: Sacrifício I | L12: =COUNTIFS(CAMISA!$V:$V,'TABELA GERAL'!L1) -> 0 | M12: =COUNTIFS(CAMISA!$V:$V,'TABELA GERAL'!M1) -> 0 | N12: =COUNTIFS(CAMISA!$V:$V,'TABELA GERAL'!N1) -> 1 | O12: =COUNTIFS(CAMISA!$V:$V,'TABELA GERAL'!O1) -> 0 | P12: =COUNTIFS(CAMISA!$V:$V,'TABELA GERAL'!P1) -> 0 | Q12: =COUNTIFS(CAMISA!$V:$V,'TABELA GERAL'!Q1) -> 0 | R12: =COUNTIFS(CAMISA!$V:$V,'TABELA GERAL'!R1) -> 0 | S12: =COUNTIFS(CAMISA!$V:$V,'TABELA GERAL'!S1) -> 0 | U12: Sacrifício I | V12: =COUNTIFS(BOTA!$V:$V,'TABELA GERAL'!V1) -> 0 | W12: =COUNTIFS(BOTA!$V:$V,'TABELA GERAL'!W1) -> 0 | X12: =COUNTIFS(BOTA!$V:$V,'TABELA GERAL'!X1) -> 0 | Y12: =COUNTIFS(BOTA!$V:$V,'TABELA GERAL'!Y1) -> 1 | Z12: =COUNTIFS(BOTA!$V:$V,'TABELA GERAL'!Z1) -> 1 | AA12: =COUNTIFS(BOTA!$V:$V,'TABELA GERAL'!AA1) -> 0 | AB12: =COUNTIFS(BOTA!$V:$V,'TABELA GERAL'!AB1) -> 0 | AC12: =COUNTIFS(BOTA!$V:$V,'TABELA GERAL'!AC1) -> 0
A13: Sacrifício II | B13: =COUNTIFS(COLAR!$X:$X,'TABELA GERAL'!B1) -> 2 | C13: =COUNTIFS(COLAR!$X:$X,'TABELA GERAL'!C1) -> 0 | D13: =COUNTIFS(COLAR!$X:$X,'TABELA GERAL'!D1) -> 0 | E13: =COUNTIFS(COLAR!$X:$X,'TABELA GERAL'!E1) -> 0 | F13: =COUNTIFS(COLAR!$X:$X,'TABELA GERAL'!F1) -> 0 | G13: =COUNTIFS(COLAR!$X:$X,'TABELA GERAL'!G1) -> 1 | H13: =COUNTIFS(COLAR!$X:$X,'TABELA GERAL'!H1) -> 0 | I13: =COUNTIFS(COLAR!$X:$X,'TABELA GERAL'!I1) -> 0 | K13: Sacrifício II | L13: =COUNTIFS(CAMISA!$X:$X,'TABELA GERAL'!L1) -> 0 | M13: =COUNTIFS(CAMISA!$X:$X,'TABELA GERAL'!M1) -> 0 | N13: =COUNTIFS(CAMISA!$X:$X,'TABELA GERAL'!N1) -> 1 | O13: =COUNTIFS(CAMISA!$X:$X,'TABELA GERAL'!O1) -> 0 | P13: =COUNTIFS(CAMISA!$X:$X,'TABELA GERAL'!P1) -> 0 | Q13: =COUNTIFS(CAMISA!$X:$X,'TABELA GERAL'!Q1) -> 2 | R13: =COUNTIFS(CAMISA!$X:$X,'TABELA GERAL'!R1) -> 0 | S13: =COUNTIFS(CAMISA!$X:$X,'TABELA GERAL'!S1) -> 1 | U13: Sacrifício II | V13: =COUNTIFS(BOTA!$X:$X,'TABELA GERAL'!V1) -> 0 | W13: =COUNTIFS(BOTA!$X:$X,'TABELA GERAL'!W1) -> 1 | X13: =COUNTIFS(BOTA!$X:$X,'TABELA GERAL'!X1) -> 0 | Y13: =COUNTIFS(BOTA!$X:$X,'TABELA GERAL'!Y1) -> 0 | Z13: =COUNTIFS(BOTA!$X:$X,'TABELA GERAL'!Z1) -> 1 | AA13: =COUNTIFS(BOTA!$X:$X,'TABELA GERAL'!AA1) -> 0 | AB13: =COUNTIFS(BOTA!$X:$X,'TABELA GERAL'!AB1) -> 0 | AC13: =COUNTIFS(BOTA!$X:$X,'TABELA GERAL'!AC1) -> 0
A14: Sacrifício III | B14: =COUNTIFS(COLAR!$Z:$Z,'TABELA GERAL'!B1) -> 0 | C14: =COUNTIFS(COLAR!$Z:$Z,'TABELA GERAL'!C1) -> 0 | D14: =COUNTIFS(COLAR!$Z:$Z,'TABELA GERAL'!D1) -> 0 | E14: =COUNTIFS(COLAR!$Z:$Z,'TABELA GERAL'!E1) -> 0 | F14: =COUNTIFS(COLAR!$Z:$Z,'TABELA GERAL'!F1) -> 1 | G14: =COUNTIFS(COLAR!$Z:$Z,'TABELA GERAL'!G1) -> 0 | H14: =COUNTIFS(COLAR!$Z:$Z,'TABELA GERAL'!H1) -> 0 | I14: =COUNTIFS(COLAR!$Z:$Z,'TABELA GERAL'!I1) -> 0 | K14: Sacrifício III | L14: =COUNTIFS(CAMISA!$Z:$Z,'TABELA GERAL'!L1) -> 1 | M14: =COUNTIFS(CAMISA!$Z:$Z,'TABELA GERAL'!M1) -> 0 | N14: =COUNTIFS(CAMISA!$Z:$Z,'TABELA GERAL'!N1) -> 1 | O14: =COUNTIFS(CAMISA!$Z:$Z,'TABELA GERAL'!O1) -> 1 | P14: =COUNTIFS(CAMISA!$Z:$Z,'TABELA GERAL'!P1) -> 1 | Q14: =COUNTIFS(CAMISA!$Z:$Z,'TABELA GERAL'!Q1) -> 0 | R14: =COUNTIFS(CAMISA!$Z:$Z,'TABELA GERAL'!R1) -> 0 | S14: =COUNTIFS(CAMISA!$Z:$Z,'TABELA GERAL'!S1) -> 1 | U14: Sacrifício III | V14: =COUNTIFS(BOTA!$Z:$Z,'TABELA GERAL'!V1) -> 0 | W14: =COUNTIFS(BOTA!$Z:$Z,'TABELA GERAL'!W1) -> 2 | X14: =COUNTIFS(BOTA!$Z:$Z,'TABELA GERAL'!X1) -> 0 | Y14: =COUNTIFS(BOTA!$Z:$Z,'TABELA GERAL'!Y1) -> 0 | Z14: =COUNTIFS(BOTA!$Z:$Z,'TABELA GERAL'!Z1) -> 2 | AA14: =COUNTIFS(BOTA!$Z:$Z,'TABELA GERAL'!AA1) -> 0 | AB14: =COUNTIFS(BOTA!$Z:$Z,'TABELA GERAL'!AB1) -> 0 | AC14: =COUNTIFS(BOTA!$Z:$Z,'TABELA GERAL'!AC1) -> 0
A15: Sacrifício IV | B15: =COUNTIFS(COLAR!$AB:$AB,'TABELA GERAL'!B1) -> 0 | C15: =COUNTIFS(COLAR!$AB:$AB,'TABELA GERAL'!C1) -> 1 | D15: =COUNTIFS(COLAR!$AB:$AB,'TABELA GERAL'!D1) -> 0 | E15: =COUNTIFS(COLAR!$AB:$AB,'TABELA GERAL'!E1) -> 1 | F15: =COUNTIFS(COLAR!$AB:$AB,'TABELA GERAL'!F1) -> 1 | G15: =COUNTIFS(COLAR!$AB:$AB,'TABELA GERAL'!G1) -> 1 | H15: =COUNTIFS(COLAR!$AB:$AB,'TABELA GERAL'!H1) -> 1 | I15: =COUNTIFS(COLAR!$AB:$AB,'TABELA GERAL'!I1) -> 0 | K15: Sacrifício IV | L15: =COUNTIFS(CAMISA!$AB:$AB,'TABELA GERAL'!L1) -> 2 | M15: =COUNTIFS(CAMISA!$AB:$AB,'TABELA GERAL'!M1) -> 1 | N15: =COUNTIFS(CAMISA!$AB:$AB,'TABELA GERAL'!N1) -> 0 | O15: =COUNTIFS(CAMISA!$AB:$AB,'TABELA GERAL'!O1) -> 1 | P15: =COUNTIFS(CAMISA!$AB:$AB,'TABELA GERAL'!P1) -> 1 | Q15: =COUNTIFS(CAMISA!$AB:$AB,'TABELA GERAL'!Q1) -> 1 | R15: =COUNTIFS(CAMISA!$AB:$AB,'TABELA GERAL'!R1) -> 1 | S15: =COUNTIFS(CAMISA!$AB:$AB,'TABELA GERAL'!S1) -> 0 | U15: Sacrifício IV | V15: =COUNTIFS(BOTA!$AB:$AB,'TABELA GERAL'!V1) -> 0 | W15: =COUNTIFS(BOTA!$AB:$AB,'TABELA GERAL'!W1) -> 1 | X15: =COUNTIFS(BOTA!$AB:$AB,'TABELA GERAL'!X1) -> 2 | Y15: =COUNTIFS(BOTA!$AB:$AB,'TABELA GERAL'!Y1) -> 3 | Z15: =COUNTIFS(BOTA!$AB:$AB,'TABELA GERAL'!Z1) -> 1 | AA15: =COUNTIFS(BOTA!$AB:$AB,'TABELA GERAL'!AA1) -> 0 | AB15: =COUNTIFS(BOTA!$AB:$AB,'TABELA GERAL'!AB1) -> 1 | AC15: =COUNTIFS(BOTA!$AB:$AB,'TABELA GERAL'!AC1) -> 1
A16: Sacrifício V | B16: =COUNTIFS(COLAR!$AD:$AD,'TABELA GERAL'!B1) -> 1 | C16: =COUNTIFS(COLAR!$AD:$AD,'TABELA GERAL'!C1) -> 0 | D16: =COUNTIFS(COLAR!$AD:$AD,'TABELA GERAL'!D1) -> 1 | E16: =COUNTIFS(COLAR!$AD:$AD,'TABELA GERAL'!E1) -> 1 | F16: =COUNTIFS(COLAR!$AD:$AD,'TABELA GERAL'!F1) -> 0 | G16: =COUNTIFS(COLAR!$AD:$AD,'TABELA GERAL'!G1) -> 0 | H16: =COUNTIFS(COLAR!$AD:$AD,'TABELA GERAL'!H1) -> 0 | I16: =COUNTIFS(COLAR!$AD:$AD,'TABELA GERAL'!I1) -> 0 | K16: Sacrifício V | L16: =COUNTIFS(CAMISA!$AD:$AD,'TABELA GERAL'!L1) -> 0 | M16: =COUNTIFS(CAMISA!$AD:$AD,'TABELA GERAL'!M1) -> 2 | N16: =COUNTIFS(CAMISA!$AD:$AD,'TABELA GERAL'!N1) -> 0 | O16: =COUNTIFS(CAMISA!$AD:$AD,'TABELA GERAL'!O1) -> 0 | P16: =COUNTIFS(CAMISA!$AD:$AD,'TABELA GERAL'!P1) -> 1 | Q16: =COUNTIFS(CAMISA!$AD:$AD,'TABELA GERAL'!Q1) -> 0 | R16: =COUNTIFS(CAMISA!$AD:$AD,'TABELA GERAL'!R1) -> 1 | S16: =COUNTIFS(CAMISA!$AD:$AD,'TABELA GERAL'!S1) -> 0 | U16: Sacrifício V | V16: =COUNTIFS(BOTA!$AD:$AD,'TABELA GERAL'!V1) -> 0 | W16: =COUNTIFS(BOTA!$AD:$AD,'TABELA GERAL'!W1) -> 0 | X16: =COUNTIFS(BOTA!$AD:$AD,'TABELA GERAL'!X1) -> 1 | Y16: =COUNTIFS(BOTA!$AD:$AD,'TABELA GERAL'!Y1) -> 1 | Z16: =COUNTIFS(BOTA!$AD:$AD,'TABELA GERAL'!Z1) -> 0 | AA16: =COUNTIFS(BOTA!$AD:$AD,'TABELA GERAL'!AA1) -> 0 | AB16: =COUNTIFS(BOTA!$AD:$AD,'TABELA GERAL'!AB1) -> 2 | AC16: =COUNTIFS(BOTA!$AD:$AD,'TABELA GERAL'!AC1) -> 0
A17: Tychel I | B17: =COUNTIFS(COLAR!$AF:$AF,'TABELA GERAL'!B1) -> 0 | C17: =COUNTIFS(COLAR!$AF:$AF,'TABELA GERAL'!C1) -> 0 | D17: =COUNTIFS(COLAR!$AF:$AF,'TABELA GERAL'!D1) -> 1 | E17: =COUNTIFS(COLAR!$AF:$AF,'TABELA GERAL'!E1) -> 0 | F17: =COUNTIFS(COLAR!$AF:$AF,'TABELA GERAL'!F1) -> 0 | G17: =COUNTIFS(COLAR!$AF:$AF,'TABELA GERAL'!G1) -> 0 | H17: =COUNTIFS(COLAR!$AF:$AF,'TABELA GERAL'!H1) -> 0 | I17: =COUNTIFS(COLAR!$AF:$AF,'TABELA GERAL'!I1) -> 0 | K17: Tychel I | L17: =COUNTIFS(CAMISA!$AF:$AF,'TABELA GERAL'!L1) -> 0 | M17: =COUNTIFS(CAMISA!$AF:$AF,'TABELA GERAL'!M1) -> 0 | N17: =COUNTIFS(CAMISA!$AF:$AF,'TABELA GERAL'!N1) -> 2 | O17: =COUNTIFS(CAMISA!$AF:$AF,'TABELA GERAL'!O1) -> 0 | P17: =COUNTIFS(CAMISA!$AF:$AF,'TABELA GERAL'!P1) -> 0 | Q17: =COUNTIFS(CAMISA!$AF:$AF,'TABELA GERAL'!Q1) -> 0 | R17: =COUNTIFS(CAMISA!$AF:$AF,'TABELA GERAL'!R1) -> 0 | S17: =COUNTIFS(CAMISA!$AF:$AF,'TABELA GERAL'!S1) -> 0 | U17: Tychel I | V17: =COUNTIFS(BOTA!$AF:$AF,'TABELA GERAL'!V1) -> 0 | W17: =COUNTIFS(BOTA!$AF:$AF,'TABELA GERAL'!W1) -> 0 | X17: =COUNTIFS(BOTA!$AF:$AF,'TABELA GERAL'!X1) -> 1 | Y17: =COUNTIFS(BOTA!$AF:$AF,'TABELA GERAL'!Y1) -> 0 | Z17: =COUNTIFS(BOTA!$AF:$AF,'TABELA GERAL'!Z1) -> 0 | AA17: =COUNTIFS(BOTA!$AF:$AF,'TABELA GERAL'!AA1) -> 0 | AB17: =COUNTIFS(BOTA!$AF:$AF,'TABELA GERAL'!AB1) -> 0 | AC17: =COUNTIFS(BOTA!$AF:$AF,'TABELA GERAL'!AC1) -> 0
A18: Tychel II | B18: =COUNTIFS(COLAR!$AH:$AH,'TABELA GERAL'!B1) -> 1 | C18: =COUNTIFS(COLAR!$AH:$AH,'TABELA GERAL'!C1) -> 0 | D18: =COUNTIFS(COLAR!$AH:$AH,'TABELA GERAL'!D1) -> 1 | E18: =COUNTIFS(COLAR!$AH:$AH,'TABELA GERAL'!E1) -> 2 | F18: =COUNTIFS(COLAR!$AH:$AH,'TABELA GERAL'!F1) -> 1 | G18: =COUNTIFS(COLAR!$AH:$AH,'TABELA GERAL'!G1) -> 1 | H18: =COUNTIFS(COLAR!$AH:$AH,'TABELA GERAL'!H1) -> 2 | I18: =COUNTIFS(COLAR!$AH:$AH,'TABELA GERAL'!I1) -> 0 | K18: Tychel II | L18: =COUNTIFS(CAMISA!$AH:$AH,'TABELA GERAL'!L1) -> 0 | M18: =COUNTIFS(CAMISA!$AH:$AH,'TABELA GERAL'!M1) -> 0 | N18: =COUNTIFS(CAMISA!$AH:$AH,'TABELA GERAL'!N1) -> 1 | O18: =COUNTIFS(CAMISA!$AH:$AH,'TABELA GERAL'!O1) -> 0 | P18: =COUNTIFS(CAMISA!$AH:$AH,'TABELA GERAL'!P1) -> 0 | Q18: =COUNTIFS(CAMISA!$AH:$AH,'TABELA GERAL'!Q1) -> 1 | R18: =COUNTIFS(CAMISA!$AH:$AH,'TABELA GERAL'!R1) -> 0 | S18: =COUNTIFS(CAMISA!$AH:$AH,'TABELA GERAL'!S1) -> 0 | U18: Tychel II | V18: =COUNTIFS(BOTA!$AH:$AH,'TABELA GERAL'!V1) -> 0 | W18: =COUNTIFS(BOTA!$AH:$AH,'TABELA GERAL'!W1) -> 0 | X18: =COUNTIFS(BOTA!$AH:$AH,'TABELA GERAL'!X1) -> 1 | Y18: =COUNTIFS(BOTA!$AH:$AH,'TABELA GERAL'!Y1) -> 1 | Z18: =COUNTIFS(BOTA!$AH:$AH,'TABELA GERAL'!Z1) -> 0 | AA18: =COUNTIFS(BOTA!$AH:$AH,'TABELA GERAL'!AA1) -> 0 | AB18: =COUNTIFS(BOTA!$AH:$AH,'TABELA GERAL'!AB1) -> 0 | AC18: =COUNTIFS(BOTA!$AH:$AH,'TABELA GERAL'!AC1) -> 0
A19: Tychel III | B19: =COUNTIFS(COLAR!$AJ:$AJ,'TABELA GERAL'!B1) -> 0 | C19: =COUNTIFS(COLAR!$AJ:$AJ,'TABELA GERAL'!C1) -> 0 | D19: =COUNTIFS(COLAR!$AJ:$AJ,'TABELA GERAL'!D1) -> 1 | E19: =COUNTIFS(COLAR!$AJ:$AJ,'TABELA GERAL'!E1) -> 1 | F19: =COUNTIFS(COLAR!$AJ:$AJ,'TABELA GERAL'!F1) -> 0 | G19: =COUNTIFS(COLAR!$AJ:$AJ,'TABELA GERAL'!G1) -> 1 | H19: =COUNTIFS(COLAR!$AJ:$AJ,'TABELA GERAL'!H1) -> 0 | I19: =COUNTIFS(COLAR!$AJ:$AJ,'TABELA GERAL'!I1) -> 0 | K19: Tychel III | L19: =COUNTIFS(CAMISA!$AJ:$AJ,'TABELA GERAL'!L1) -> 0 | M19: =COUNTIFS(CAMISA!$AJ:$AJ,'TABELA GERAL'!M1) -> 0 | N19: =COUNTIFS(CAMISA!$AJ:$AJ,'TABELA GERAL'!N1) -> 0 | O19: =COUNTIFS(CAMISA!$AJ:$AJ,'TABELA GERAL'!O1) -> 0 | P19: =COUNTIFS(CAMISA!$AJ:$AJ,'TABELA GERAL'!P1) -> 1 | Q19: =COUNTIFS(CAMISA!$AJ:$AJ,'TABELA GERAL'!Q1) -> 0 | R19: =COUNTIFS(CAMISA!$AJ:$AJ,'TABELA GERAL'!R1) -> 0 | S19: =COUNTIFS(CAMISA!$AJ:$AJ,'TABELA GERAL'!S1) -> 0 | U19: Tychel III | V19: =COUNTIFS(BOTA!$AJ:$AJ,'TABELA GERAL'!V1) -> 0 | W19: =COUNTIFS(BOTA!$AJ:$AJ,'TABELA GERAL'!W1) -> 0 | X19: =COUNTIFS(BOTA!$AJ:$AJ,'TABELA GERAL'!X1) -> 0 | Y19: =COUNTIFS(BOTA!$AJ:$AJ,'TABELA GERAL'!Y1) -> 0 | Z19: =COUNTIFS(BOTA!$AJ:$AJ,'TABELA GERAL'!Z1) -> 0 | AA19: =COUNTIFS(BOTA!$AJ:$AJ,'TABELA GERAL'!AA1) -> 1 | AB19: =COUNTIFS(BOTA!$AJ:$AJ,'TABELA GERAL'!AB1) -> 0 | AC19: =COUNTIFS(BOTA!$AJ:$AJ,'TABELA GERAL'!AC1) -> 0
A20: Tychel IV | B20: =COUNTIFS(COLAR!$AL:$AL,'TABELA GERAL'!B1) -> 2 | C20: =COUNTIFS(COLAR!$AL:$AL,'TABELA GERAL'!C1) -> 1 | D20: =COUNTIFS(COLAR!$AL:$AL,'TABELA GERAL'!D1) -> 0 | E20: =COUNTIFS(COLAR!$AL:$AL,'TABELA GERAL'!E1) -> 2 | F20: =COUNTIFS(COLAR!$AL:$AL,'TABELA GERAL'!F1) -> 0 | G20: =COUNTIFS(COLAR!$AL:$AL,'TABELA GERAL'!G1) -> 0 | H20: =COUNTIFS(COLAR!$AL:$AL,'TABELA GERAL'!H1) -> 1 | I20: =COUNTIFS(COLAR!$AL:$AL,'TABELA GERAL'!I1) -> 0 | K20: Tychel IV | L20: =COUNTIFS(CAMISA!$AL:$AL,'TABELA GERAL'!L1) -> 0 | M20: =COUNTIFS(CAMISA!$AL:$AL,'TABELA GERAL'!M1) -> 2 | N20: =COUNTIFS(CAMISA!$AL:$AL,'TABELA GERAL'!N1) -> 0 | O20: =COUNTIFS(CAMISA!$AL:$AL,'TABELA GERAL'!O1) -> 2 | P20: =COUNTIFS(CAMISA!$AL:$AL,'TABELA GERAL'!P1) -> 1 | Q20: =COUNTIFS(CAMISA!$AL:$AL,'TABELA GERAL'!Q1) -> 4 | R20: =COUNTIFS(CAMISA!$AL:$AL,'TABELA GERAL'!R1) -> 2 | S20: =COUNTIFS(CAMISA!$AL:$AL,'TABELA GERAL'!S1) -> 1 | U20: Tychel IV | V20: =COUNTIFS(BOTA!$AL:$AL,'TABELA GERAL'!V1) -> 1 | W20: =COUNTIFS(BOTA!$AL:$AL,'TABELA GERAL'!W1) -> 2 | X20: =COUNTIFS(BOTA!$AL:$AL,'TABELA GERAL'!X1) -> 1 | Y20: =COUNTIFS(BOTA!$AL:$AL,'TABELA GERAL'!Y1) -> 0 | Z20: =COUNTIFS(BOTA!$AL:$AL,'TABELA GERAL'!Z1) -> 0 | AA20: =COUNTIFS(BOTA!$AL:$AL,'TABELA GERAL'!AA1) -> 2 | AB20: =COUNTIFS(BOTA!$AL:$AL,'TABELA GERAL'!AB1) -> 6 | AC20: =COUNTIFS(BOTA!$AL:$AL,'TABELA GERAL'!AC1) -> 1
A21: Tychel V | B21: =COUNTIFS(COLAR!$AN:$AN,'TABELA GERAL'!B1) -> 0 | C21: =COUNTIFS(COLAR!$AN:$AN,'TABELA GERAL'!C1) -> 0 | D21: =COUNTIFS(COLAR!$AN:$AN,'TABELA GERAL'!D1) -> 0 | E21: =COUNTIFS(COLAR!$AN:$AN,'TABELA GERAL'!E1) -> 1 | F21: =COUNTIFS(COLAR!$AN:$AN,'TABELA GERAL'!F1) -> 1 | G21: =COUNTIFS(COLAR!$AN:$AN,'TABELA GERAL'!G1) -> 1 | H21: =COUNTIFS(COLAR!$AN:$AN,'TABELA GERAL'!H1) -> 0 | I21: =COUNTIFS(COLAR!$AN:$AN,'TABELA GERAL'!I1) -> 0 | K21: Tychel V | L21: =COUNTIFS(CAMISA!$AN:$AN,'TABELA GERAL'!L1) -> 0 | M21: =COUNTIFS(CAMISA!$AN:$AN,'TABELA GERAL'!M1) -> 1 | N21: =COUNTIFS(CAMISA!$AN:$AN,'TABELA GERAL'!N1) -> 0 | O21: =COUNTIFS(CAMISA!$AN:$AN,'TABELA GERAL'!O1) -> 1 | P21: =COUNTIFS(CAMISA!$AN:$AN,'TABELA GERAL'!P1) -> 0 | Q21: =COUNTIFS(CAMISA!$AN:$AN,'TABELA GERAL'!Q1) -> 1 | R21: =COUNTIFS(CAMISA!$AN:$AN,'TABELA GERAL'!R1) -> 0 | S21: =COUNTIFS(CAMISA!$AN:$AN,'TABELA GERAL'!S1) -> 1 | U21: Tychel V | V21: =COUNTIFS(BOTA!$AN:$AN,'TABELA GERAL'!V1) -> 0 | W21: =COUNTIFS(BOTA!$AN:$AN,'TABELA GERAL'!W1) -> 0 | X21: =COUNTIFS(BOTA!$AN:$AN,'TABELA GERAL'!X1) -> 0 | Y21: =COUNTIFS(BOTA!$AN:$AN,'TABELA GERAL'!Y1) -> 0 | Z21: =COUNTIFS(BOTA!$AN:$AN,'TABELA GERAL'!Z1) -> 0 | AA21: =COUNTIFS(BOTA!$AN:$AN,'TABELA GERAL'!AA1) -> 1 | AB21: =COUNTIFS(BOTA!$AN:$AN,'TABELA GERAL'!AB1) -> 0 | AC21: =COUNTIFS(BOTA!$AN:$AN,'TABELA GERAL'!AC1) -> 3
A22: Azrael I | B22: =COUNTIFS(COLAR!$AP:$AP,'TABELA GERAL'!B1) -> 0 | C22: =COUNTIFS(COLAR!$AP:$AP,'TABELA GERAL'!C1) -> 0 | D22: =COUNTIFS(COLAR!$AP:$AP,'TABELA GERAL'!D1) -> 1 | E22: =COUNTIFS(COLAR!$AP:$AP,'TABELA GERAL'!E1) -> 0 | F22: =COUNTIFS(COLAR!$AP:$AP,'TABELA GERAL'!F1) -> 0 | G22: =COUNTIFS(COLAR!$AP:$AP,'TABELA GERAL'!G1) -> 0 | H22: =COUNTIFS(COLAR!$AP:$AP,'TABELA GERAL'!H1) -> 0 | I22: =COUNTIFS(COLAR!$AP:$AP,'TABELA GERAL'!I1) -> 0 | K22: Azrael I | L22: =COUNTIFS(CAMISA!$AP:$AP,'TABELA GERAL'!L1) -> 0 | M22: =COUNTIFS(CAMISA!$AP:$AP,'TABELA GERAL'!M1) -> 0 | N22: =COUNTIFS(CAMISA!$AP:$AP,'TABELA GERAL'!N1) -> 0 | O22: =COUNTIFS(CAMISA!$AP:$AP,'TABELA GERAL'!O1) -> 0 | P22: =COUNTIFS(CAMISA!$AP:$AP,'TABELA GERAL'!P1) -> 0 | Q22: =COUNTIFS(CAMISA!$AP:$AP,'TABELA GERAL'!Q1) -> 1 | R22: =COUNTIFS(CAMISA!$AP:$AP,'TABELA GERAL'!R1) -> 0 | S22: =COUNTIFS(CAMISA!$AP:$AP,'TABELA GERAL'!S1) -> 0 | U22: Azrael I | V22: =COUNTIFS(BOTA!$AP:$AP,'TABELA GERAL'!V1) -> 0 | W22: =COUNTIFS(BOTA!$AP:$AP,'TABELA GERAL'!W1) -> 0 | X22: =COUNTIFS(BOTA!$AP:$AP,'TABELA GERAL'!X1) -> 1 | Y22: =COUNTIFS(BOTA!$AP:$AP,'TABELA GERAL'!Y1) -> 1 | Z22: =COUNTIFS(BOTA!$AP:$AP,'TABELA GERAL'!Z1) -> 0 | AA22: =COUNTIFS(BOTA!$AP:$AP,'TABELA GERAL'!AA1) -> 0 | AB22: =COUNTIFS(BOTA!$AP:$AP,'TABELA GERAL'!AB1) -> 0 | AC22: =COUNTIFS(BOTA!$AP:$AP,'TABELA GERAL'!AC1) -> 0
A23: Azrael II | B23: =COUNTIFS(COLAR!$AR:$AR,'TABELA GERAL'!B1) -> 0 | C23: =COUNTIFS(COLAR!$AR:$AR,'TABELA GERAL'!C1) -> 0 | D23: =COUNTIFS(COLAR!$AR:$AR,'TABELA GERAL'!D1) -> 0 | E23: =COUNTIFS(COLAR!$AR:$AR,'TABELA GERAL'!E1) -> 0 | F23: =COUNTIFS(COLAR!$AR:$AR,'TABELA GERAL'!F1) -> 0 | G23: =COUNTIFS(COLAR!$AR:$AR,'TABELA GERAL'!G1) -> 0 | H23: =COUNTIFS(COLAR!$AR:$AR,'TABELA GERAL'!H1) -> 0 | I23: =COUNTIFS(COLAR!$AR:$AR,'TABELA GERAL'!I1) -> 0 | K23: Azrael II | L23: =COUNTIFS(CAMISA!$AR:$AR,'TABELA GERAL'!L1) -> 1 | M23: =COUNTIFS(CAMISA!$AR:$AR,'TABELA GERAL'!M1) -> 0 | N23: =COUNTIFS(CAMISA!$AR:$AR,'TABELA GERAL'!N1) -> 0 | O23: =COUNTIFS(CAMISA!$AR:$AR,'TABELA GERAL'!O1) -> 0 | P23: =COUNTIFS(CAMISA!$AR:$AR,'TABELA GERAL'!P1) -> 0 | Q23: =COUNTIFS(CAMISA!$AR:$AR,'TABELA GERAL'!Q1) -> 0 | R23: =COUNTIFS(CAMISA!$AR:$AR,'TABELA GERAL'!R1) -> 0 | S23: =COUNTIFS(CAMISA!$AR:$AR,'TABELA GERAL'!S1) -> 0 | U23: Azrael II | V23: =COUNTIFS(BOTA!$AR:$AR,'TABELA GERAL'!V1) -> 0 | W23: =COUNTIFS(BOTA!$AR:$AR,'TABELA GERAL'!W1) -> 0 | X23: =COUNTIFS(BOTA!$AR:$AR,'TABELA GERAL'!X1) -> 0 | Y23: =COUNTIFS(BOTA!$AR:$AR,'TABELA GERAL'!Y1) -> 1 | Z23: =COUNTIFS(BOTA!$AR:$AR,'TABELA GERAL'!Z1) -> 0 | AA23: =COUNTIFS(BOTA!$AR:$AR,'TABELA GERAL'!AA1) -> 0 | AB23: =COUNTIFS(BOTA!$AR:$AR,'TABELA GERAL'!AB1) -> 0 | AC23: =COUNTIFS(BOTA!$AR:$AR,'TABELA GERAL'!AC1) -> 0
A24: Azrael III | B24: =COUNTIFS(COLAR!$AT:$AT,'TABELA GERAL'!B1) -> 0 | C24: =COUNTIFS(COLAR!$AT:$AT,'TABELA GERAL'!C1) -> 1 | D24: =COUNTIFS(COLAR!$AT:$AT,'TABELA GERAL'!D1) -> 0 | E24: =COUNTIFS(COLAR!$AT:$AT,'TABELA GERAL'!E1) -> 0 | F24: =COUNTIFS(COLAR!$AT:$AT,'TABELA GERAL'!F1) -> 3 | G24: =COUNTIFS(COLAR!$AT:$AT,'TABELA GERAL'!G1) -> 0 | H24: =COUNTIFS(COLAR!$AT:$AT,'TABELA GERAL'!H1) -> 0 | I24: =COUNTIFS(COLAR!$AT:$AT,'TABELA GERAL'!I1) -> 0 | K24: Azrael III | L24: =COUNTIFS(CAMISA!$AT:$AT,'TABELA GERAL'!L1) -> 0 | M24: =COUNTIFS(CAMISA!$AT:$AT,'TABELA GERAL'!M1) -> 0 | N24: =COUNTIFS(CAMISA!$AT:$AT,'TABELA GERAL'!N1) -> 0 | O24: =COUNTIFS(CAMISA!$AT:$AT,'TABELA GERAL'!O1) -> 0 | P24: =COUNTIFS(CAMISA!$AT:$AT,'TABELA GERAL'!P1) -> 0 | Q24: =COUNTIFS(CAMISA!$AT:$AT,'TABELA GERAL'!Q1) -> 1 | R24: =COUNTIFS(CAMISA!$AT:$AT,'TABELA GERAL'!R1) -> 0 | S24: =COUNTIFS(CAMISA!$AT:$AT,'TABELA GERAL'!S1) -> 0 | U24: Azrael III | V24: =COUNTIFS(BOTA!$AT:$AT,'TABELA GERAL'!V1) -> 0 | W24: =COUNTIFS(BOTA!$AT:$AT,'TABELA GERAL'!W1) -> 0 | X24: =COUNTIFS(BOTA!$AT:$AT,'TABELA GERAL'!X1) -> 0 | Y24: =COUNTIFS(BOTA!$AT:$AT,'TABELA GERAL'!Y1) -> 0 | Z24: =COUNTIFS(BOTA!$AT:$AT,'TABELA GERAL'!Z1) -> 1 | AA24: =COUNTIFS(BOTA!$AT:$AT,'TABELA GERAL'!AA1) -> 1 | AB24: =COUNTIFS(BOTA!$AT:$AT,'TABELA GERAL'!AB1) -> 0 | AC24: =COUNTIFS(BOTA!$AT:$AT,'TABELA GERAL'!AC1) -> 0
A25: Azrael IV | B25: =COUNTIFS(COLAR!$AV:$AV,'TABELA GERAL'!B1) -> 0 | C25: =COUNTIFS(COLAR!$AV:$AV,'TABELA GERAL'!C1) -> 1 | D25: =COUNTIFS(COLAR!$AV:$AV,'TABELA GERAL'!D1) -> 1 | E25: =COUNTIFS(COLAR!$AV:$AV,'TABELA GERAL'!E1) -> 1 | F25: =COUNTIFS(COLAR!$AV:$AV,'TABELA GERAL'!F1) -> 2 | G25: =COUNTIFS(COLAR!$AV:$AV,'TABELA GERAL'!G1) -> 1 | H25: =COUNTIFS(COLAR!$AV:$AV,'TABELA GERAL'!H1) -> 1 | I25: =COUNTIFS(COLAR!$AV:$AV,'TABELA GERAL'!I1) -> 0 | K25: Azrael IV | L25: =COUNTIFS(CAMISA!$AV:$AV,'TABELA GERAL'!L1) -> 1 | M25: =COUNTIFS(CAMISA!$AV:$AV,'TABELA GERAL'!M1) -> 1 | N25: =COUNTIFS(CAMISA!$AV:$AV,'TABELA GERAL'!N1) -> 0 | O25: =COUNTIFS(CAMISA!$AV:$AV,'TABELA GERAL'!O1) -> 2 | P25: =COUNTIFS(CAMISA!$AV:$AV,'TABELA GERAL'!P1) -> 0 | Q25: =COUNTIFS(CAMISA!$AV:$AV,'TABELA GERAL'!Q1) -> 0 | R25: =COUNTIFS(CAMISA!$AV:$AV,'TABELA GERAL'!R1) -> 2 | S25: =COUNTIFS(CAMISA!$AV:$AV,'TABELA GERAL'!S1) -> 1 | U25: Azrael IV | V25: =COUNTIFS(BOTA!$AV:$AV,'TABELA GERAL'!V1) -> 0 | W25: =COUNTIFS(BOTA!$AV:$AV,'TABELA GERAL'!W1) -> 0 | X25: =COUNTIFS(BOTA!$AV:$AV,'TABELA GERAL'!X1) -> 0 | Y25: =COUNTIFS(BOTA!$AV:$AV,'TABELA GERAL'!Y1) -> 1 | Z25: =COUNTIFS(BOTA!$AV:$AV,'TABELA GERAL'!Z1) -> 1 | AA25: =COUNTIFS(BOTA!$AV:$AV,'TABELA GERAL'!AA1) -> 1 | AB25: =COUNTIFS(BOTA!$AV:$AV,'TABELA GERAL'!AB1) -> 1 | AC25: =COUNTIFS(BOTA!$AV:$AV,'TABELA GERAL'!AC1) -> 3
A26: Azrael V | B26: =COUNTIFS(COLAR!$AX:$AX,'TABELA GERAL'!B1) -> 0 | C26: =COUNTIFS(COLAR!$AX:$AX,'TABELA GERAL'!C1) -> 0 | D26: =COUNTIFS(COLAR!$AX:$AX,'TABELA GERAL'!D1) -> 1 | E26: =COUNTIFS(COLAR!$AX:$AX,'TABELA GERAL'!E1) -> 0 | F26: =COUNTIFS(COLAR!$AX:$AX,'TABELA GERAL'!F1) -> 2 | G26: =COUNTIFS(COLAR!$AX:$AX,'TABELA GERAL'!G1) -> 1 | H26: =COUNTIFS(COLAR!$AX:$AX,'TABELA GERAL'!H1) -> 0 | I26: =COUNTIFS(COLAR!$AX:$AX,'TABELA GERAL'!I1) -> 0 | K26: Azrael V | L26: =COUNTIFS(CAMISA!$AX:$AX,'TABELA GERAL'!L1) -> 0 | M26: =COUNTIFS(CAMISA!$AX:$AX,'TABELA GERAL'!M1) -> 0 | N26: =COUNTIFS(CAMISA!$AX:$AX,'TABELA GERAL'!N1) -> 2 | O26: =COUNTIFS(CAMISA!$AX:$AX,'TABELA GERAL'!O1) -> 0 | P26: =COUNTIFS(CAMISA!$AX:$AX,'TABELA GERAL'!P1) -> 1 | Q26: =COUNTIFS(CAMISA!$AX:$AX,'TABELA GERAL'!Q1) -> 3 | R26: =COUNTIFS(CAMISA!$AX:$AX,'TABELA GERAL'!R1) -> 1 | S26: =COUNTIFS(CAMISA!$AX:$AX,'TABELA GERAL'!S1) -> 0 | U26: Azrael V | V26: =COUNTIFS(BOTA!$AX:$AX,'TABELA GERAL'!V1) -> 0 | W26: =COUNTIFS(BOTA!$AX:$AX,'TABELA GERAL'!W1) -> 0 | X26: =COUNTIFS(BOTA!$AX:$AX,'TABELA GERAL'!X1) -> 1 | Y26: =COUNTIFS(BOTA!$AX:$AX,'TABELA GERAL'!Y1) -> 2 | Z26: =COUNTIFS(BOTA!$AX:$AX,'TABELA GERAL'!Z1) -> 0 | AA26: =COUNTIFS(BOTA!$AX:$AX,'TABELA GERAL'!AA1) -> 0 | AB26: =COUNTIFS(BOTA!$AX:$AX,'TABELA GERAL'!AB1) -> 0 | AC26: =COUNTIFS(BOTA!$AX:$AX,'TABELA GERAL'!AC1) -> 0
A28: COLAR | B28: CHEFE | C28: ETERNID | D28: MARTE | E28: FINALID | F28: ORIGEM | G28: PILAR | H28: TROVÃO | I28: HO-OH | K28: CAMISA | L28: CHEFE | M28: ETERNID | N28: MARTE | O28: FINALID | P28: ORIGEM | Q28: PILAR | R28: TROVÃO | S28: HO-OH | U28: BOTA | V28: CHEFE | W28: ETERNID | X28: MARTE | Y28: FINALID | Z28: ORIGEM | AA28: PILAR | AB28: TROVÃO | AC28: HO-OH
A29: Titânio I | B29: =IFERROR(IF(B2/(SUM(B2:I2))=0,"",B2/(SUM(B2:I2))),"") | C29: =IFERROR(IF(C2/(SUM(B2:I2))=0,"",C2/(SUM(B2:I2))),"") | D29: =IFERROR(IF(D2/(SUM(B2:I2))=0,"",D2/(SUM(B2:I2))),"") | E29: =IFERROR(IF(E2/(SUM(B2:I2))=0,"",E2/(SUM(B2:I2))),"") | F29: =IFERROR(IF(F2/(SUM(B2:I2))=0,"",F2/(SUM(B2:I2))),"") -> 1 | G29: =IFERROR(IF(G2/(SUM(B2:I2))=0,"",G2/(SUM(B2:I2))),"") | H29: =IFERROR(IF(H2/(SUM(B2:I2))=0,"",H2/(SUM(B2:I2))),"") | I29: =IFERROR(IF(I2/(SUM(B2:I2))=0,"",I2/(SUM(B2:I2))),"") | K29: Titânio I | L29: =IFERROR(IF(L2/(SUM(L2:S2))=0,"",L2/(SUM(L2:S2))),"") | M29: =IFERROR(IF(M2/(SUM(L2:S2))=0,"",M2/(SUM(L2:S2))),"") | N29: =IFERROR(IF(N2/(SUM(L2:S2))=0,"",N2/(SUM(L2:S2))),"") -> 1 | O29: =IFERROR(IF(O2/(SUM(L2:S2))=0,"",O2/(SUM(L2:S2))),"") | P29: =IFERROR(IF(P2/(SUM(L2:S2))=0,"",P2/(SUM(L2:S2))),"") | Q29: =IFERROR(IF(Q2/(SUM(L2:S2))=0,"",Q2/(SUM(L2:S2))),"") | R29: =IFERROR(IF(R2/(SUM(L2:S2))=0,"",R2/(SUM(L2:S2))),"") | S29: =IFERROR(IF(S2/(SUM(L2:S2))=0,"",S2/(SUM(L2:S2))),"") | U29: Titânio I | V29: =IFERROR(IF(V2/(SUM(V2:AC2))=0,"",V2/(SUM(V2:AC2))),"") -> 0.33333333 | W29: =IFERROR(IF(W2/(SUM(V2:AC2))=0,"",W2/(SUM(V2:AC2))),"") | X29: =IFERROR(IF(X2/(SUM(V2:AC2))=0,"",X2/(SUM(V2:AC2))),"") | Y29: =IFERROR(IF(Y2/(SUM(V2:AC2))=0,"",Y2/(SUM(V2:AC2))),"") | Z29: =IFERROR(IF(Z2/(SUM(V2:AC2))=0,"",Z2/(SUM(V2:AC2))),"") -> 0.66666667 | AA29: =IFERROR(IF(AA2/(SUM(V2:AC2))=0,"",AA2/(SUM(V2:AC2))),"") | AB29: =IFERROR(IF(AB2/(SUM(V2:AC2))=0,"",AB2/(SUM(V2:AC2))),"") | AC29: =IFERROR(IF(AC2/(SUM(V2:AC2))=0,"",AC2/(SUM(V2:AC2))),"")
A30: Titânio II | B30: =IFERROR(IF(B3/(SUM(B3:I3))=0,"",B3/(SUM(B3:I3))),"") | C30: =IFERROR(IF(C3/(SUM(B3:I3))=0,"",C3/(SUM(B3:I3))),"") | D30: =IFERROR(IF(D3/(SUM(B3:I3))=0,"",D3/(SUM(B3:I3))),"") -> 0.33333333 | E30: =IFERROR(IF(E3/(SUM(B3:I3))=0,"",E3/(SUM(B3:I3))),"") | F30: =IFERROR(IF(F3/(SUM(B3:I3))=0,"",F3/(SUM(B3:I3))),"") -> 0.66666667 | G30: =IFERROR(IF(G3/(SUM(B3:I3))=0,"",G3/(SUM(B3:I3))),"") | H30: =IFERROR(IF(H3/(SUM(B3:I3))=0,"",H3/(SUM(B3:I3))),"") | I30: =IFERROR(IF(I3/(SUM(B3:I3))=0,"",I3/(SUM(B3:I3))),"") | K30: Titânio II | L30: =IFERROR(IF(L3/(SUM(L3:S3))=0,"",L3/(SUM(L3:S3))),"") | M30: =IFERROR(IF(M3/(SUM(L3:S3))=0,"",M3/(SUM(L3:S3))),"") -> 0.14285714 | N30: =IFERROR(IF(N3/(SUM(L3:S3))=0,"",N3/(SUM(L3:S3))),"") | O30: =IFERROR(IF(O3/(SUM(L3:S3))=0,"",O3/(SUM(L3:S3))),"") -> 0.14285714 | P30: =IFERROR(IF(P3/(SUM(L3:S3))=0,"",P3/(SUM(L3:S3))),"") -> 0.14285714 | Q30: =IFERROR(IF(Q3/(SUM(L3:S3))=0,"",Q3/(SUM(L3:S3))),"") -> 0.42857143 | R30: =IFERROR(IF(R3/(SUM(L3:S3))=0,"",R3/(SUM(L3:S3))),"") | S30: =IFERROR(IF(S3/(SUM(L3:S3))=0,"",S3/(SUM(L3:S3))),"") -> 0.14285714 | U30: Titânio II | V30: =IFERROR(IF(V3/(SUM(V3:AC3))=0,"",V3/(SUM(V3:AC3))),"") | W30: =IFERROR(IF(W3/(SUM(V3:AC3))=0,"",W3/(SUM(V3:AC3))),"") | X30: =IFERROR(IF(X3/(SUM(V3:AC3))=0,"",X3/(SUM(V3:AC3))),"") -> 0.5 | Y30: =IFERROR(IF(Y3/(SUM(V3:AC3))=0,"",Y3/(SUM(V3:AC3))),"") | Z30: =IFERROR(IF(Z3/(SUM(V3:AC3))=0,"",Z3/(SUM(V3:AC3))),"") -> 0.5 | AA30: =IFERROR(IF(AA3/(SUM(V3:AC3))=0,"",AA3/(SUM(V3:AC3))),"") | AB30: =IFERROR(IF(AB3/(SUM(V3:AC3))=0,"",AB3/(SUM(V3:AC3))),"") | AC30: =IFERROR(IF(AC3/(SUM(V3:AC3))=0,"",AC3/(SUM(V3:AC3))),"")
A31: Titânio III | B31: =IFERROR(IF(B4/(SUM(B4:I4))=0,"",B4/(SUM(B4:I4))),"") | C31: =IFERROR(IF(C4/(SUM(B4:I4))=0,"",C4/(SUM(B4:I4))),"") | D31: =IFERROR(IF(D4/(SUM(B4:I4))=0,"",D4/(SUM(B4:I4))),"") -> 0.33333333 | E31: =IFERROR(IF(E4/(SUM(B4:I4))=0,"",E4/(SUM(B4:I4))),"") -> 0.33333333 | F31: =IFERROR(IF(F4/(SUM(B4:I4))=0,"",F4/(SUM(B4:I4))),"") -> 0.33333333 | G31: =IFERROR(IF(G4/(SUM(B4:I4))=0,"",G4/(SUM(B4:I4))),"") | H31: =IFERROR(IF(H4/(SUM(B4:I4))=0,"",H4/(SUM(B4:I4))),"") | I31: =IFERROR(IF(I4/(SUM(B4:I4))=0,"",I4/(SUM(B4:I4))),"") | K31: Titânio III | L31: =IFERROR(IF(L4/(SUM(L4:S4))=0,"",L4/(SUM(L4:S4))),"") | M31: =IFERROR(IF(M4/(SUM(L4:S4))=0,"",M4/(SUM(L4:S4))),"") | N31: =IFERROR(IF(N4/(SUM(L4:S4))=0,"",N4/(SUM(L4:S4))),"") | O31: =IFERROR(IF(O4/(SUM(L4:S4))=0,"",O4/(SUM(L4:S4))),"") | P31: =IFERROR(IF(P4/(SUM(L4:S4))=0,"",P4/(SUM(L4:S4))),"") -> 1 | Q31: =IFERROR(IF(Q4/(SUM(L4:S4))=0,"",Q4/(SUM(L4:S4))),"") | R31: =IFERROR(IF(R4/(SUM(L4:S4))=0,"",R4/(SUM(L4:S4))),"") | S31: =IFERROR(IF(S4/(SUM(L4:S4))=0,"",S4/(SUM(L4:S4))),"") | U31: Titânio III | V31: =IFERROR(IF(V4/(SUM(V4:AC4))=0,"",V4/(SUM(V4:AC4))),"") | W31: =IFERROR(IF(W4/(SUM(V4:AC4))=0,"",W4/(SUM(V4:AC4))),"") | X31: =IFERROR(IF(X4/(SUM(V4:AC4))=0,"",X4/(SUM(V4:AC4))),"") -> 1 | Y31: =IFERROR(IF(Y4/(SUM(V4:AC4))=0,"",Y4/(SUM(V4:AC4))),"") | Z31: =IFERROR(IF(Z4/(SUM(V4:AC4))=0,"",Z4/(SUM(V4:AC4))),"") | AA31: =IFERROR(IF(AA4/(SUM(V4:AC4))=0,"",AA4/(SUM(V4:AC4))),"") | AB31: =IFERROR(IF(AB4/(SUM(V4:AC4))=0,"",AB4/(SUM(V4:AC4))),"") | AC31: =IFERROR(IF(AC4/(SUM(V4:AC4))=0,"",AC4/(SUM(V4:AC4))),"")
A32: Titânio IV | B32: =IFERROR(IF(B5/(SUM(B5:I5))=0,"",B5/(SUM(B5:I5))),"") -> 0.2 | C32: =IFERROR(IF(C5/(SUM(B5:I5))=0,"",C5/(SUM(B5:I5))),"") -> 0.6 | D32: =IFERROR(IF(D5/(SUM(B5:I5))=0,"",D5/(SUM(B5:I5))),"") | E32: =IFERROR(IF(E5/(SUM(B5:I5))=0,"",E5/(SUM(B5:I5))),"") | F32: =IFERROR(IF(F5/(SUM(B5:I5))=0,"",F5/(SUM(B5:I5))),"") | G32: =IFERROR(IF(G5/(SUM(B5:I5))=0,"",G5/(SUM(B5:I5))),"") | H32: =IFERROR(IF(H5/(SUM(B5:I5))=0,"",H5/(SUM(B5:I5))),"") -> 0.2 | I32: =IFERROR(IF(I5/(SUM(B5:I5))=0,"",I5/(SUM(B5:I5))),"") | K32: Titânio IV | L32: =IFERROR(IF(L5/(SUM(L5:S5))=0,"",L5/(SUM(L5:S5))),"") | M32: =IFERROR(IF(M5/(SUM(L5:S5))=0,"",M5/(SUM(L5:S5))),"") | N32: =IFERROR(IF(N5/(SUM(L5:S5))=0,"",N5/(SUM(L5:S5))),"") | O32: =IFERROR(IF(O5/(SUM(L5:S5))=0,"",O5/(SUM(L5:S5))),"") -> 0.4 | P32: =IFERROR(IF(P5/(SUM(L5:S5))=0,"",P5/(SUM(L5:S5))),"") -> 0.4 | Q32: =IFERROR(IF(Q5/(SUM(L5:S5))=0,"",Q5/(SUM(L5:S5))),"") | R32: =IFERROR(IF(R5/(SUM(L5:S5))=0,"",R5/(SUM(L5:S5))),"") | S32: =IFERROR(IF(S5/(SUM(L5:S5))=0,"",S5/(SUM(L5:S5))),"") -> 0.2 | U32: Titânio IV | V32: =IFERROR(IF(V5/(SUM(V5:AC5))=0,"",V5/(SUM(V5:AC5))),"") | W32: =IFERROR(IF(W5/(SUM(V5:AC5))=0,"",W5/(SUM(V5:AC5))),"") -> 0.25 | X32: =IFERROR(IF(X5/(SUM(V5:AC5))=0,"",X5/(SUM(V5:AC5))),"") | Y32: =IFERROR(IF(Y5/(SUM(V5:AC5))=0,"",Y5/(SUM(V5:AC5))),"") | Z32: =IFERROR(IF(Z5/(SUM(V5:AC5))=0,"",Z5/(SUM(V5:AC5))),"") -> 0.25 | AA32: =IFERROR(IF(AA5/(SUM(V5:AC5))=0,"",AA5/(SUM(V5:AC5))),"") -> 0.25 | AB32: =IFERROR(IF(AB5/(SUM(V5:AC5))=0,"",AB5/(SUM(V5:AC5))),"") -> 0.25 | AC32: =IFERROR(IF(AC5/(SUM(V5:AC5))=0,"",AC5/(SUM(V5:AC5))),"")
A33: Titânio V | B33: =IFERROR(IF(B6/(SUM(B6:I6))=0,"",B6/(SUM(B6:I6))),"") | C33: =IFERROR(IF(C6/(SUM(B6:I6))=0,"",C6/(SUM(B6:I6))),"") | D33: =IFERROR(IF(D6/(SUM(B6:I6))=0,"",D6/(SUM(B6:I6))),"") | E33: =IFERROR(IF(E6/(SUM(B6:I6))=0,"",E6/(SUM(B6:I6))),"") -> 0.66666667 | F33: =IFERROR(IF(F6/(SUM(B6:I6))=0,"",F6/(SUM(B6:I6))),"") -> 0.33333333 | G33: =IFERROR(IF(G6/(SUM(B6:I6))=0,"",G6/(SUM(B6:I6))),"") | H33: =IFERROR(IF(H6/(SUM(B6:I6))=0,"",H6/(SUM(B6:I6))),"") | I33: =IFERROR(IF(I6/(SUM(B6:I6))=0,"",I6/(SUM(B6:I6))),"") | K33: Titânio V | L33: =IFERROR(IF(L6/(SUM(L6:S6))=0,"",L6/(SUM(L6:S6))),"") | M33: =IFERROR(IF(M6/(SUM(L6:S6))=0,"",M6/(SUM(L6:S6))),"") | N33: =IFERROR(IF(N6/(SUM(L6:S6))=0,"",N6/(SUM(L6:S6))),"") -> 0.14285714 | O33: =IFERROR(IF(O6/(SUM(L6:S6))=0,"",O6/(SUM(L6:S6))),"") -> 0.28571429 | P33: =IFERROR(IF(P6/(SUM(L6:S6))=0,"",P6/(SUM(L6:S6))),"") | Q33: =IFERROR(IF(Q6/(SUM(L6:S6))=0,"",Q6/(SUM(L6:S6))),"") -> 0.57142857 | R33: =IFERROR(IF(R6/(SUM(L6:S6))=0,"",R6/(SUM(L6:S6))),"") | S33: =IFERROR(IF(S6/(SUM(L6:S6))=0,"",S6/(SUM(L6:S6))),"") | U33: Titânio V | V33: =IFERROR(IF(V6/(SUM(V6:AC6))=0,"",V6/(SUM(V6:AC6))),"") | W33: =IFERROR(IF(W6/(SUM(V6:AC6))=0,"",W6/(SUM(V6:AC6))),"") | X33: =IFERROR(IF(X6/(SUM(V6:AC6))=0,"",X6/(SUM(V6:AC6))),"") -> 0.4 | Y33: =IFERROR(IF(Y6/(SUM(V6:AC6))=0,"",Y6/(SUM(V6:AC6))),"") | Z33: =IFERROR(IF(Z6/(SUM(V6:AC6))=0,"",Z6/(SUM(V6:AC6))),"") -> 0.4 | AA33: =IFERROR(IF(AA6/(SUM(V6:AC6))=0,"",AA6/(SUM(V6:AC6))),"") | AB33: =IFERROR(IF(AB6/(SUM(V6:AC6))=0,"",AB6/(SUM(V6:AC6))),"") | AC33: =IFERROR(IF(AC6/(SUM(V6:AC6))=0,"",AC6/(SUM(V6:AC6))),"") -> 0.2
A34: Estrelar I | B34: =IFERROR(IF(B7/(SUM(B7:I7))=0,"",B7/(SUM(B7:I7))),"") -> 0.33333333 | C34: =IFERROR(IF(C7/(SUM(B7:I7))=0,"",C7/(SUM(B7:I7))),"") | D34: =IFERROR(IF(D7/(SUM(B7:I7))=0,"",D7/(SUM(B7:I7))),"") | E34: =IFERROR(IF(E7/(SUM(B7:I7))=0,"",E7/(SUM(B7:I7))),"") -> 0.66666667 | F34: =IFERROR(IF(F7/(SUM(B7:I7))=0,"",F7/(SUM(B7:I7))),"") | G34: =IFERROR(IF(G7/(SUM(B7:I7))=0,"",G7/(SUM(B7:I7))),"") | H34: =IFERROR(IF(H7/(SUM(B7:I7))=0,"",H7/(SUM(B7:I7))),"") | I34: =IFERROR(IF(I7/(SUM(B7:I7))=0,"",I7/(SUM(B7:I7))),"") | K34: Estrelar I | L34: =IFERROR(IF(L7/(SUM(L7:S7))=0,"",L7/(SUM(L7:S7))),"") | M34: =IFERROR(IF(M7/(SUM(L7:S7))=0,"",M7/(SUM(L7:S7))),"") | N34: =IFERROR(IF(N7/(SUM(L7:S7))=0,"",N7/(SUM(L7:S7))),"") -> 0.25 | O34: =IFERROR(IF(O7/(SUM(L7:S7))=0,"",O7/(SUM(L7:S7))),"") | P34: =IFERROR(IF(P7/(SUM(L7:S7))=0,"",P7/(SUM(L7:S7))),"") -> 0.75 | Q34: =IFERROR(IF(Q7/(SUM(L7:S7))=0,"",Q7/(SUM(L7:S7))),"") | R34: =IFERROR(IF(R7/(SUM(L7:S7))=0,"",R7/(SUM(L7:S7))),"") | S34: =IFERROR(IF(S7/(SUM(L7:S7))=0,"",S7/(SUM(L7:S7))),"") | U34: Estrelar I | V34: =IFERROR(IF(V7/(SUM(V7:AC7))=0,"",V7/(SUM(V7:AC7))),"") | W34: =IFERROR(IF(W7/(SUM(V7:AC7))=0,"",W7/(SUM(V7:AC7))),"") -> 1 | X34: =IFERROR(IF(X7/(SUM(V7:AC7))=0,"",X7/(SUM(V7:AC7))),"") | Y34: =IFERROR(IF(Y7/(SUM(V7:AC7))=0,"",Y7/(SUM(V7:AC7))),"") | Z34: =IFERROR(IF(Z7/(SUM(V7:AC7))=0,"",Z7/(SUM(V7:AC7))),"") | AA34: =IFERROR(IF(AA7/(SUM(V7:AC7))=0,"",AA7/(SUM(V7:AC7))),"") | AB34: =IFERROR(IF(AB7/(SUM(V7:AC7))=0,"",AB7/(SUM(V7:AC7))),"") | AC34: =IFERROR(IF(AC7/(SUM(V7:AC7))=0,"",AC7/(SUM(V7:AC7))),"")
A35: Estrelar II | B35: =IFERROR(IF(B8/(SUM(B8:I8))=0,"",B8/(SUM(B8:I8))),"") | C35: =IFERROR(IF(C8/(SUM(B8:I8))=0,"",C8/(SUM(B8:I8))),"") | D35: =IFERROR(IF(D8/(SUM(B8:I8))=0,"",D8/(SUM(B8:I8))),"") | E35: =IFERROR(IF(E8/(SUM(B8:I8))=0,"",E8/(SUM(B8:I8))),"") -> 0.5 | F35: =IFERROR(IF(F8/(SUM(B8:I8))=0,"",F8/(SUM(B8:I8))),"") | G35: =IFERROR(IF(G8/(SUM(B8:I8))=0,"",G8/(SUM(B8:I8))),"") -> 0.5 | H35: =IFERROR(IF(H8/(SUM(B8:I8))=0,"",H8/(SUM(B8:I8))),"") | I35: =IFERROR(IF(I8/(SUM(B8:I8))=0,"",I8/(SUM(B8:I8))),"") | K35: Estrelar II | L35: =IFERROR(IF(L8/(SUM(L8:S8))=0,"",L8/(SUM(L8:S8))),"") | M35: =IFERROR(IF(M8/(SUM(L8:S8))=0,"",M8/(SUM(L8:S8))),"") | N35: =IFERROR(IF(N8/(SUM(L8:S8))=0,"",N8/(SUM(L8:S8))),"") | O35: =IFERROR(IF(O8/(SUM(L8:S8))=0,"",O8/(SUM(L8:S8))),"") | P35: =IFERROR(IF(P8/(SUM(L8:S8))=0,"",P8/(SUM(L8:S8))),"") -> 1 | Q35: =IFERROR(IF(Q8/(SUM(L8:S8))=0,"",Q8/(SUM(L8:S8))),"") | R35: =IFERROR(IF(R8/(SUM(L8:S8))=0,"",R8/(SUM(L8:S8))),"") | S35: =IFERROR(IF(S8/(SUM(L8:S8))=0,"",S8/(SUM(L8:S8))),"") | U35: Estrelar II | V35: =IFERROR(IF(V8/(SUM(V8:AC8))=0,"",V8/(SUM(V8:AC8))),"") | W35: =IFERROR(IF(W8/(SUM(V8:AC8))=0,"",W8/(SUM(V8:AC8))),"") | X35: =IFERROR(IF(X8/(SUM(V8:AC8))=0,"",X8/(SUM(V8:AC8))),"") | Y35: =IFERROR(IF(Y8/(SUM(V8:AC8))=0,"",Y8/(SUM(V8:AC8))),"") | Z35: =IFERROR(IF(Z8/(SUM(V8:AC8))=0,"",Z8/(SUM(V8:AC8))),"") | AA35: =IFERROR(IF(AA8/(SUM(V8:AC8))=0,"",AA8/(SUM(V8:AC8))),"") -> 1 | AB35: =IFERROR(IF(AB8/(SUM(V8:AC8))=0,"",AB8/(SUM(V8:AC8))),"") | AC35: =IFERROR(IF(AC8/(SUM(V8:AC8))=0,"",AC8/(SUM(V8:AC8))),"")
A36: Estrelar III | B36: =IFERROR(IF(B9/(SUM(B9:I9))=0,"",B9/(SUM(B9:I9))),"") | C36: =IFERROR(IF(C9/(SUM(B9:I9))=0,"",C9/(SUM(B9:I9))),"") | D36: =IFERROR(IF(D9/(SUM(B9:I9))=0,"",D9/(SUM(B9:I9))),"") -> 1 | E36: =IFERROR(IF(E9/(SUM(B9:I9))=0,"",E9/(SUM(B9:I9))),"") | F36: =IFERROR(IF(F9/(SUM(B9:I9))=0,"",F9/(SUM(B9:I9))),"") | G36: =IFERROR(IF(G9/(SUM(B9:I9))=0,"",G9/(SUM(B9:I9))),"") | H36: =IFERROR(IF(H9/(SUM(B9:I9))=0,"",H9/(SUM(B9:I9))),"") | I36: =IFERROR(IF(I9/(SUM(B9:I9))=0,"",I9/(SUM(B9:I9))),"") | K36: Estrelar III | L36: =IFERROR(IF(L9/(SUM(L9:S9))=0,"",L9/(SUM(L9:S9))),"") | M36: =IFERROR(IF(M9/(SUM(L9:S9))=0,"",M9/(SUM(L9:S9))),"") | N36: =IFERROR(IF(N9/(SUM(L9:S9))=0,"",N9/(SUM(L9:S9))),"") | O36: =IFERROR(IF(O9/(SUM(L9:S9))=0,"",O9/(SUM(L9:S9))),"") | P36: =IFERROR(IF(P9/(SUM(L9:S9))=0,"",P9/(SUM(L9:S9))),"") | Q36: =IFERROR(IF(Q9/(SUM(L9:S9))=0,"",Q9/(SUM(L9:S9))),"") -> 1 | R36: =IFERROR(IF(R9/(SUM(L9:S9))=0,"",R9/(SUM(L9:S9))),"") | S36: =IFERROR(IF(S9/(SUM(L9:S9))=0,"",S9/(SUM(L9:S9))),"") | U36: Estrelar III | V36: =IFERROR(IF(V9/(SUM(V9:AC9))=0,"",V9/(SUM(V9:AC9))),"") | W36: =IFERROR(IF(W9/(SUM(V9:AC9))=0,"",W9/(SUM(V9:AC9))),"") | X36: =IFERROR(IF(X9/(SUM(V9:AC9))=0,"",X9/(SUM(V9:AC9))),"") | Y36: =IFERROR(IF(Y9/(SUM(V9:AC9))=0,"",Y9/(SUM(V9:AC9))),"") | Z36: =IFERROR(IF(Z9/(SUM(V9:AC9))=0,"",Z9/(SUM(V9:AC9))),"") | AA36: =IFERROR(IF(AA9/(SUM(V9:AC9))=0,"",AA9/(SUM(V9:AC9))),"") | AB36: =IFERROR(IF(AB9/(SUM(V9:AC9))=0,"",AB9/(SUM(V9:AC9))),"") | AC36: =IFERROR(IF(AC9/(SUM(V9:AC9))=0,"",AC9/(SUM(V9:AC9))),"")
A37: Estrelar IV | B37: =IFERROR(IF(B10/(SUM(B10:I10))=0,"",B10/(SUM(B10:I10))),"") -> 0.33333333 | C37: =IFERROR(IF(C10/(SUM(B10:I10))=0,"",C10/(SUM(B10:I10))),"") | D37: =IFERROR(IF(D10/(SUM(B10:I10))=0,"",D10/(SUM(B10:I10))),"") -> 0.33333333 | E37: =IFERROR(IF(E10/(SUM(B10:I10))=0,"",E10/(SUM(B10:I10))),"") | F37: =IFERROR(IF(F10/(SUM(B10:I10))=0,"",F10/(SUM(B10:I10))),"") | G37: =IFERROR(IF(G10/(SUM(B10:I10))=0,"",G10/(SUM(B10:I10))),"") -> 0.33333333 | H37: =IFERROR(IF(H10/(SUM(B10:I10))=0,"",H10/(SUM(B10:I10))),"") | I37: =IFERROR(IF(I10/(SUM(B10:I10))=0,"",I10/(SUM(B10:I10))),"") | K37: Estrelar IV | L37: =IFERROR(IF(L10/(SUM(L10:S10))=0,"",L10/(SUM(L10:S10))),"") -> 0.25 | M37: =IFERROR(IF(M10/(SUM(L10:S10))=0,"",M10/(SUM(L10:S10))),"") -> 0.25 | N37: =IFERROR(IF(N10/(SUM(L10:S10))=0,"",N10/(SUM(L10:S10))),"") | O37: =IFERROR(IF(O10/(SUM(L10:S10))=0,"",O10/(SUM(L10:S10))),"") | P37: =IFERROR(IF(P10/(SUM(L10:S10))=0,"",P10/(SUM(L10:S10))),"") | Q37: =IFERROR(IF(Q10/(SUM(L10:S10))=0,"",Q10/(SUM(L10:S10))),"") -> 0.25 | R37: =IFERROR(IF(R10/(SUM(L10:S10))=0,"",R10/(SUM(L10:S10))),"") | S37: =IFERROR(IF(S10/(SUM(L10:S10))=0,"",S10/(SUM(L10:S10))),"") -> 0.25 | U37: Estrelar IV | V37: =IFERROR(IF(V10/(SUM(V10:AC10))=0,"",V10/(SUM(V10:AC10))),"") | W37: =IFERROR(IF(W10/(SUM(V10:AC10))=0,"",W10/(SUM(V10:AC10))),"") | X37: =IFERROR(IF(X10/(SUM(V10:AC10))=0,"",X10/(SUM(V10:AC10))),"") | Y37: =IFERROR(IF(Y10/(SUM(V10:AC10))=0,"",Y10/(SUM(V10:AC10))),"") -> 0.33333333 | Z37: =IFERROR(IF(Z10/(SUM(V10:AC10))=0,"",Z10/(SUM(V10:AC10))),"") -> 0.33333333 | AA37: =IFERROR(IF(AA10/(SUM(V10:AC10))=0,"",AA10/(SUM(V10:AC10))),"") -> 0.33333333 | AB37: =IFERROR(IF(AB10/(SUM(V10:AC10))=0,"",AB10/(SUM(V10:AC10))),"") | AC37: =IFERROR(IF(AC10/(SUM(V10:AC10))=0,"",AC10/(SUM(V10:AC10))),"")
A38: Estrelar V | B38: =IFERROR(IF(B11/(SUM(B11:I11))=0,"",B11/(SUM(B11:I11))),"") | C38: =IFERROR(IF(C11/(SUM(B11:I11))=0,"",C11/(SUM(B11:I11))),"") -> 0.5 | D38: =IFERROR(IF(D11/(SUM(B11:I11))=0,"",D11/(SUM(B11:I11))),"") | E38: =IFERROR(IF(E11/(SUM(B11:I11))=0,"",E11/(SUM(B11:I11))),"") -> 0.5 | F38: =IFERROR(IF(F11/(SUM(B11:I11))=0,"",F11/(SUM(B11:I11))),"") | G38: =IFERROR(IF(G11/(SUM(B11:I11))=0,"",G11/(SUM(B11:I11))),"") | H38: =IFERROR(IF(H11/(SUM(B11:I11))=0,"",H11/(SUM(B11:I11))),"") | I38: =IFERROR(IF(I11/(SUM(B11:I11))=0,"",I11/(SUM(B11:I11))),"") | K38: Estrelar V | L38: =IFERROR(IF(L11/(SUM(L11:S11))=0,"",L11/(SUM(L11:S11))),"") | M38: =IFERROR(IF(M11/(SUM(L11:S11))=0,"",M11/(SUM(L11:S11))),"") -> 0.5 | N38: =IFERROR(IF(N11/(SUM(L11:S11))=0,"",N11/(SUM(L11:S11))),"") | O38: =IFERROR(IF(O11/(SUM(L11:S11))=0,"",O11/(SUM(L11:S11))),"") | P38: =IFERROR(IF(P11/(SUM(L11:S11))=0,"",P11/(SUM(L11:S11))),"") | Q38: =IFERROR(IF(Q11/(SUM(L11:S11))=0,"",Q11/(SUM(L11:S11))),"") -> 0.5 | R38: =IFERROR(IF(R11/(SUM(L11:S11))=0,"",R11/(SUM(L11:S11))),"") | S38: =IFERROR(IF(S11/(SUM(L11:S11))=0,"",S11/(SUM(L11:S11))),"") | U38: Estrelar V | V38: =IFERROR(IF(V11/(SUM(V11:AC11))=0,"",V11/(SUM(V11:AC11))),"") | W38: =IFERROR(IF(W11/(SUM(V11:AC11))=0,"",W11/(SUM(V11:AC11))),"") | X38: =IFERROR(IF(X11/(SUM(V11:AC11))=0,"",X11/(SUM(V11:AC11))),"") | Y38: =IFERROR(IF(Y11/(SUM(V11:AC11))=0,"",Y11/(SUM(V11:AC11))),"") -> 1 | Z38: =IFERROR(IF(Z11/(SUM(V11:AC11))=0,"",Z11/(SUM(V11:AC11))),"") | AA38: =IFERROR(IF(AA11/(SUM(V11:AC11))=0,"",AA11/(SUM(V11:AC11))),"") | AB38: =IFERROR(IF(AB11/(SUM(V11:AC11))=0,"",AB11/(SUM(V11:AC11))),"") | AC38: =IFERROR(IF(AC11/(SUM(V11:AC11))=0,"",AC11/(SUM(V11:AC11))),"")
A39: Sacrifício I | B39: =IFERROR(IF(B12/(SUM(B12:I12))=0,"",B12/(SUM(B12:I12))),"") | C39: =IFERROR(IF(C12/(SUM(B12:I12))=0,"",C12/(SUM(B12:I12))),"") -> 0.33333333 | D39: =IFERROR(IF(D12/(SUM(B12:I12))=0,"",D12/(SUM(B12:I12))),"") -> 0.33333333 | E39: =IFERROR(IF(E12/(SUM(B12:I12))=0,"",E12/(SUM(B12:I12))),"") | F39: =IFERROR(IF(F12/(SUM(B12:I12))=0,"",F12/(SUM(B12:I12))),"") -> 0.33333333 | G39: =IFERROR(IF(G12/(SUM(B12:I12))=0,"",G12/(SUM(B12:I12))),"") | H39: =IFERROR(IF(H12/(SUM(B12:I12))=0,"",H12/(SUM(B12:I12))),"") | I39: =IFERROR(IF(I12/(SUM(B12:I12))=0,"",I12/(SUM(B12:I12))),"") | K39: Sacrifício I | L39: =IFERROR(IF(L12/(SUM(L12:S12))=0,"",L12/(SUM(L12:S12))),"") | M39: =IFERROR(IF(M12/(SUM(L12:S12))=0,"",M12/(SUM(L12:S12))),"") | N39: =IFERROR(IF(N12/(SUM(L12:S12))=0,"",N12/(SUM(L12:S12))),"") -> 1 | O39: =IFERROR(IF(O12/(SUM(L12:S12))=0,"",O12/(SUM(L12:S12))),"") | P39: =IFERROR(IF(P12/(SUM(L12:S12))=0,"",P12/(SUM(L12:S12))),"") | Q39: =IFERROR(IF(Q12/(SUM(L12:S12))=0,"",Q12/(SUM(L12:S12))),"") | R39: =IFERROR(IF(R12/(SUM(L12:S12))=0,"",R12/(SUM(L12:S12))),"") | S39: =IFERROR(IF(S12/(SUM(L12:S12))=0,"",S12/(SUM(L12:S12))),"") | U39: Sacrifício I | V39: =IFERROR(IF(V12/(SUM(V12:AC12))=0,"",V12/(SUM(V12:AC12))),"") | W39: =IFERROR(IF(W12/(SUM(V12:AC12))=0,"",W12/(SUM(V12:AC12))),"") | X39: =IFERROR(IF(X12/(SUM(V12:AC12))=0,"",X12/(SUM(V12:AC12))),"") | Y39: =IFERROR(IF(Y12/(SUM(V12:AC12))=0,"",Y12/(SUM(V12:AC12))),"") -> 0.5 | Z39: =IFERROR(IF(Z12/(SUM(V12:AC12))=0,"",Z12/(SUM(V12:AC12))),"") -> 0.5 | AA39: =IFERROR(IF(AA12/(SUM(V12:AC12))=0,"",AA12/(SUM(V12:AC12))),"") | AB39: =IFERROR(IF(AB12/(SUM(V12:AC12))=0,"",AB12/(SUM(V12:AC12))),"") | AC39: =IFERROR(IF(AC12/(SUM(V12:AC12))=0,"",AC12/(SUM(V12:AC12))),"")
A40: Sacrifício II | B40: =IFERROR(IF(B13/(SUM(B13:I13))=0,"",B13/(SUM(B13:I13))),"") -> 0.66666667 | C40: =IFERROR(IF(C13/(SUM(B13:I13))=0,"",C13/(SUM(B13:I13))),"") | D40: =IFERROR(IF(D13/(SUM(B13:I13))=0,"",D13/(SUM(B13:I13))),"") | E40: =IFERROR(IF(E13/(SUM(B13:I13))=0,"",E13/(SUM(B13:I13))),"") | F40: =IFERROR(IF(F13/(SUM(B13:I13))=0,"",F13/(SUM(B13:I13))),"") | G40: =IFERROR(IF(G13/(SUM(B13:I13))=0,"",G13/(SUM(B13:I13))),"") -> 0.33333333 | H40: =IFERROR(IF(H13/(SUM(B13:I13))=0,"",H13/(SUM(B13:I13))),"") | I40: =IFERROR(IF(I13/(SUM(B13:I13))=0,"",I13/(SUM(B13:I13))),"") | K40: Sacrifício II | L40: =IFERROR(IF(L13/(SUM(L13:S13))=0,"",L13/(SUM(L13:S13))),"") | M40: =IFERROR(IF(M13/(SUM(L13:S13))=0,"",M13/(SUM(L13:S13))),"") | N40: =IFERROR(IF(N13/(SUM(L13:S13))=0,"",N13/(SUM(L13:S13))),"") -> 0.25 | O40: =IFERROR(IF(O13/(SUM(L13:S13))=0,"",O13/(SUM(L13:S13))),"") | P40: =IFERROR(IF(P13/(SUM(L13:S13))=0,"",P13/(SUM(L13:S13))),"") | Q40: =IFERROR(IF(Q13/(SUM(L13:S13))=0,"",Q13/(SUM(L13:S13))),"") -> 0.5 | R40: =IFERROR(IF(R13/(SUM(L13:S13))=0,"",R13/(SUM(L13:S13))),"") | S40: =IFERROR(IF(S13/(SUM(L13:S13))=0,"",S13/(SUM(L13:S13))),"") -> 0.25 | U40: Sacrifício II | V40: =IFERROR(IF(V13/(SUM(V13:AC13))=0,"",V13/(SUM(V13:AC13))),"") | W40: =IFERROR(IF(W13/(SUM(V13:AC13))=0,"",W13/(SUM(V13:AC13))),"") -> 0.5 | X40: =IFERROR(IF(X13/(SUM(V13:AC13))=0,"",X13/(SUM(V13:AC13))),"") | Y40: =IFERROR(IF(Y13/(SUM(V13:AC13))=0,"",Y13/(SUM(V13:AC13))),"") | Z40: =IFERROR(IF(Z13/(SUM(V13:AC13))=0,"",Z13/(SUM(V13:AC13))),"") -> 0.5 | AA40: =IFERROR(IF(AA13/(SUM(V13:AC13))=0,"",AA13/(SUM(V13:AC13))),"") | AB40: =IFERROR(IF(AB13/(SUM(V13:AC13))=0,"",AB13/(SUM(V13:AC13))),"") | AC40: =IFERROR(IF(AC13/(SUM(V13:AC13))=0,"",AC13/(SUM(V13:AC13))),"")
... A53: Azrael V | B53: =IFERROR(IF(B26/(SUM(B26:I26))=0,"",B26/(SUM(B26:I26))),"") | C53: =IFERROR(IF(C26/(SUM(B26:I26))=0,"",C26/(SUM(B26:I26))),"") | D53: =IFERROR(IF(D26/(SUM(B26:I26))=0,"",D26/(SUM(B26:I26))),"") -> 0.25 | E53: =IFERROR(IF(E26/(SUM(B26:I26))=0,"",E26/(SUM(B26:I26))),"") | F53: =IFERROR(IF(F26/(SUM(B26:I26))=0,"",F26/(SUM(B26:I26))),"") -> 0.5 | G53: =IFERROR(IF(G26/(SUM(B26:I26))=0,"",G26/(SUM(B26:I26))),"") -> 0.25 | H53: =IFERROR(IF(H26/(SUM(B26:I26))=0,"",H26/(SUM(B26:I26))),"") | I53: =IFERROR(IF(I26/(SUM(B26:I26))=0,"",I26/(SUM(B26:I26))),"") | K53: Azrael V | L53: =IFERROR(IF(L26/(SUM(L26:S26))=0,"",L26/(SUM(L26:S26))),"") | M53: =IFERROR(IF(M26/(SUM(L26:S26))=0,"",M26/(SUM(L26:S26))),"") | N53: =IFERROR(IF(N26/(SUM(L26:S26))=0,"",N26/(SUM(L26:S26))),"") -> 0.28571429 | O53: =IFERROR(IF(O26/(SUM(L26:S26))=0,"",O26/(SUM(L26:S26))),"") | P53: =IFERROR(IF(P26/(SUM(L26:S26))=0,"",P26/(SUM(L26:S26))),"") -> 0.14285714 | Q53: =IFERROR(IF(Q26/(SUM(L26:S26))=0,"",Q26/(SUM(L26:S26))),"") -> 0.42857143 | R53: =IFERROR(IF(R26/(SUM(L26:S26))=0,"",R26/(SUM(L26:S26))),"") -> 0.14285714 | S53: =IFERROR(IF(S26/(SUM(L26:S26))=0,"",S26/(SUM(L26:S26))),"") | U53: Azrael V | V53: =IFERROR(IF(V26/(SUM(V26:AC26))=0,"",V26/(SUM(V26:AC26))),"") | W53: =IFERROR(IF(W26/(SUM(V26:AC26))=0,"",W26/(SUM(V26:AC26))),"") | X53: =IFERROR(IF(X26/(SUM(V26:AC26))=0,"",X26/(SUM(V26:AC26))),"") -> 0.33333333 | Y53: =IFERROR(IF(Y26/(SUM(V26:AC26))=0,"",Y26/(SUM(V26:AC26))),"") -> 0.66666667 | Z53: =IFERROR(IF(Z26/(SUM(V26:AC26))=0,"",Z26/(SUM(V26:AC26))),"") | AA53: =IFERROR(IF(AA26/(SUM(V26:AC26))=0,"",AA26/(SUM(V26:AC26))),"") | AB53: =IFERROR(IF(AB26/(SUM(V26:AC26))=0,"",AB26/(SUM(V26:AC26))),"") | AC53: =IFERROR(IF(AC26/(SUM(V26:AC26))=0,"",AC26/(SUM(V26:AC26))),"")

Sheet TABELA POR HORA
A1: HORA | C1: 0 | D1: 1 | E1: 2 | F1: 3 | G1: 4 | H1: 5 | I1: 6 | J1: 7
C2: 8 | D2: 9 | E2: 10 | F2: 11 | G2: 12 | H2: 13 | I2: 14 | J2: 15
C3: 16 | D3: 17 | E3: 18 | F3: 19 | G3: 20 | H3: 21 | I3: 22 | J3: 23
B5: COLAR | C5: CHEFE | D5: ETERNID | E5: MARTE | F5: FINALID | G5: ORIGEM | H5: PILAR | I5: TROVÃO | J5: HO-OH | L5: CAMISA | M5: CHEFE | N5: ETERNID | O5: MARTE | P5: FINALID | Q5: ORIGEM | R5: PILAR | S5: TROVÃO | T5: HO-OH | V5: BOTA | W5: CHEFE | X5: ETERNID | Y5: MARTE | Z5: FINALID | AA5: ORIGEM | AB5: PILAR | AC5: TROVÃO | AD5: HO-OH
B6: Titânio I | C6: =COUNTIFS(COLAR!$B:$B,'TABELA POR HORA'!C5,COLAR!$C:$C,C31) -> 0 | D6: =COUNTIFS(COLAR!$B:$B,'TABELA POR HORA'!D5,COLAR!$C:$C,C31) -> 0 | E6: =COUNTIFS(COLAR!$B:$B,'TABELA POR HORA'!E5,COLAR!$C:$C,C31) -> 0 | F6: =COUNTIFS(COLAR!$B:$B,'TABELA POR HORA'!F5,COLAR!$C:$C,C31) -> 0 | G6: =COUNTIFS(COLAR!$B:$B,'TABELA POR HORA'!G5,COLAR!$C:$C,C31) -> 0 | H6: =COUNTIFS(COLAR!$B:$B,'TABELA POR HORA'!H5,COLAR!$C:$C,C31) -> 0 | I6: =COUNTIFS(COLAR!$B:$B,'TABELA POR HORA'!I5,COLAR!$C:$C,C31) -> 0 | J6: =COUNTIFS(COLAR!$B:$B,'TABELA POR HORA'!J5,COLAR!$C:$C,C31) -> 0 | L6: Titânio I | M6: =COUNTIFS(CAMISA!$B:$B,'TABELA POR HORA'!M5,CAMISA!$C:$C,C31) -> 0 | N6: =COUNTIFS(CAMISA!$B:$B,'TABELA POR HORA'!N5,CAMISA!$C:$C,C31) -> 0 | O6: =COUNTIFS(CAMISA!$B:$B,'TABELA POR HORA'!O5,CAMISA!$C:$C,C31) -> 0 | P6: =COUNTIFS(CAMISA!$B:$B,'TABELA POR HORA'!P5,CAMISA!$C:$C,C31) -> 0 | Q6: =COUNTIFS(CAMISA!$B:$B,'TABELA POR HORA'!Q5,CAMISA!$C:$C,C31) -> 0 | R6: =COUNTIFS(CAMISA!$B:$B,'TABELA POR HORA'!R5,CAMISA!$C:$C,C31) -> 0 | S6: =COUNTIFS(CAMISA!$B:$B,'TABELA POR HORA'!S5,CAMISA!$C:$C,C31) -> 0 | T6: =COUNTIFS(CAMISA!$B:$B,'TABELA POR HORA'!T5,CAMISA!$C:$C,C31) -> 0 | V6: Titânio I | W6: =COUNTIFS(BOTA!$B:$B,'TABELA POR HORA'!W5,BOTA!$C:$C,C31) -> 0 | X6: =COUNTIFS(BOTA!$B:$B,'TABELA POR HORA'!X5,BOTA!$C:$C,C31) -> 0 | Y6: =COUNTIFS(BOTA!$B:$B,'TABELA POR HORA'!Y5,BOTA!$C:$C,C31) -> 0 | Z6: =COUNTIFS(BOTA!$B:$B,'TABELA POR HORA'!Z5,BOTA!$C:$C,C31) -> 0 | AA6: =COUNTIFS(BOTA!$B:$B,'TABELA POR HORA'!AA5,BOTA!$C:$C,C31) -> 0 | AB6: =COUNTIFS(BOTA!$B:$B,'TABELA POR HORA'!AB5,BOTA!$C:$C,C31) -> 0 | AC6: =COUNTIFS(BOTA!$B:$B,'TABELA POR HORA'!AC5,BOTA!$C:$C,C31) -> 0 | AD6: =COUNTIFS(BOTA!$B:$B,'TABELA POR HORA'!AD5,BOTA!$C:$C,C31) -> 0
